2018-04-24 11:26:05,301 39126-123145475117056 ERROR: Failed when updating the prices [in /Users/lgp/Desktop/python-workspace/demo/app/jobs.py:49]
Traceback (most recent call last):
  File "/Users/lgp/Desktop/python-workspace/demo/app/jobs.py", line 47, in huobi_update_prices
    kline_huobi(app)
NameError: global name 'kline_huobi' is not defined
2018-04-24 11:27:05,560 39126-123145475117056 ERROR: Failed when updating the prices [in /Users/lgp/Desktop/python-workspace/demo/app/jobs.py:49]
Traceback (most recent call last):
  File "/Users/lgp/Desktop/python-workspace/demo/app/jobs.py", line 47, in huobi_update_prices
    kline_huobi(app)
NameError: global name 'kline_huobi' is not defined
2018-04-24 11:28:05,772 39126-123145475117056 ERROR: Failed when updating the prices [in /Users/lgp/Desktop/python-workspace/demo/app/jobs.py:49]
Traceback (most recent call last):
  File "/Users/lgp/Desktop/python-workspace/demo/app/jobs.py", line 47, in huobi_update_prices
    kline_huobi(app)
NameError: global name 'kline_huobi' is not defined
2018-04-24 11:29:18,158 39139-123145536524288 ERROR: Failed when updating the huobi prices [in /Users/lgp/Desktop/python-workspace/demo/app/jobs.py:49]
Traceback (most recent call last):
  File "/Users/lgp/Desktop/python-workspace/demo/app/jobs.py", line 47, in huobi_update_prices
    kline_huobi(app)
NameError: global name 'kline_huobi' is not defined
2018-04-24 11:30:18,372 39139-123145536524288 ERROR: Failed when updating the huobi prices [in /Users/lgp/Desktop/python-workspace/demo/app/jobs.py:49]
Traceback (most recent call last):
  File "/Users/lgp/Desktop/python-workspace/demo/app/jobs.py", line 47, in huobi_update_prices
    kline_huobi(app)
NameError: global name 'kline_huobi' is not defined
2018-04-24 11:32:02,042 39151-123145522499584 ERROR: Failed when updating the huobi prices [in /Users/lgp/Desktop/python-workspace/demo/app/jobs.py:49]
Traceback (most recent call last):
  File "/Users/lgp/Desktop/python-workspace/demo/app/jobs.py", line 47, in huobi_update_prices
    kline_huobi(app)
NameError: global name 'kline_huobi' is not defined
2018-04-24 11:41:43,962 39221-123145499729920 ERROR: Failed when updating the huobi prices [in /Users/lgp/Desktop/python-workspace/demo/app/jobs.py:49]
Traceback (most recent call last):
  File "/Users/lgp/Desktop/python-workspace/demo/app/jobs.py", line 47, in huobi_update_prices
    blog.kline_huobi(app)
NameError: global name 'blog' is not defined
2018-04-24 11:42:44,191 39221-123145499729920 ERROR: Failed when updating the huobi prices [in /Users/lgp/Desktop/python-workspace/demo/app/jobs.py:49]
Traceback (most recent call last):
  File "/Users/lgp/Desktop/python-workspace/demo/app/jobs.py", line 47, in huobi_update_prices
    blog.kline_huobi(app)
NameError: global name 'blog' is not defined
2018-04-24 11:43:44,402 39221-123145499729920 ERROR: Failed when updating the huobi prices [in /Users/lgp/Desktop/python-workspace/demo/app/jobs.py:49]
Traceback (most recent call last):
  File "/Users/lgp/Desktop/python-workspace/demo/app/jobs.py", line 47, in huobi_update_prices
    blog.kline_huobi(app)
NameError: global name 'blog' is not defined
2018-04-24 11:44:44,660 39221-123145499729920 ERROR: Failed when updating the huobi prices [in /Users/lgp/Desktop/python-workspace/demo/app/jobs.py:49]
Traceback (most recent call last):
  File "/Users/lgp/Desktop/python-workspace/demo/app/jobs.py", line 47, in huobi_update_prices
    blog.kline_huobi(app)
NameError: global name 'blog' is not defined
2018-04-24 11:45:43,865 39221-123145499729920 ERROR: Failed when updating binance the prices [in /Users/lgp/Desktop/python-workspace/demo/app/jobs.py:59]
Traceback (most recent call last):
  File "/Users/lgp/Desktop/python-workspace/demo/app/jobs.py", line 57, in binance_update_prices
    blog.kline_binance(app)
NameError: global name 'blog' is not defined
2018-04-24 11:45:44,886 39221-123145499729920 ERROR: Failed when updating the huobi prices [in /Users/lgp/Desktop/python-workspace/demo/app/jobs.py:49]
Traceback (most recent call last):
  File "/Users/lgp/Desktop/python-workspace/demo/app/jobs.py", line 47, in huobi_update_prices
    blog.kline_huobi(app)
NameError: global name 'blog' is not defined
2018-04-24 11:46:45,112 39221-123145499729920 ERROR: Failed when updating the huobi prices [in /Users/lgp/Desktop/python-workspace/demo/app/jobs.py:49]
Traceback (most recent call last):
  File "/Users/lgp/Desktop/python-workspace/demo/app/jobs.py", line 47, in huobi_update_prices
    blog.kline_huobi(app)
NameError: global name 'blog' is not defined
2018-04-24 11:47:45,333 39221-123145499729920 ERROR: Failed when updating the huobi prices [in /Users/lgp/Desktop/python-workspace/demo/app/jobs.py:49]
Traceback (most recent call last):
  File "/Users/lgp/Desktop/python-workspace/demo/app/jobs.py", line 47, in huobi_update_prices
    blog.kline_huobi(app)
NameError: global name 'blog' is not defined
2018-04-24 11:49:07,337 39239-123145318764544 ERROR: Failed when updating the huobi prices [in /Users/lgp/Desktop/python-workspace/demo/app/jobs.py:49]
Traceback (most recent call last):
  File "/Users/lgp/Desktop/python-workspace/demo/app/jobs.py", line 47, in huobi_update_prices
    kline_huobi(app)
NameError: global name 'kline_huobi' is not defined
2018-04-24 11:50:30,696 39259-123145474834432 ERROR: Failed when updating the huobi prices [in /Users/lgp/Desktop/python-workspace/demo/app/jobs.py:49]
Traceback (most recent call last):
  File "/Users/lgp/Desktop/python-workspace/demo/app/jobs.py", line 47, in huobi_update_prices
    kline_huobi(app)
NameError: global name 'kline_huobi' is not defined
2018-04-24 11:51:30,918 39259-123145474834432 ERROR: Failed when updating the huobi prices [in /Users/lgp/Desktop/python-workspace/demo/app/jobs.py:49]
Traceback (most recent call last):
  File "/Users/lgp/Desktop/python-workspace/demo/app/jobs.py", line 47, in huobi_update_prices
    kline_huobi(app)
NameError: global name 'kline_huobi' is not defined
2018-04-24 11:52:31,139 39259-123145474834432 ERROR: Failed when updating the huobi prices [in /Users/lgp/Desktop/python-workspace/demo/app/jobs.py:49]
Traceback (most recent call last):
  File "/Users/lgp/Desktop/python-workspace/demo/app/jobs.py", line 47, in huobi_update_prices
    kline_huobi(app)
NameError: global name 'kline_huobi' is not defined
2018-04-24 11:54:25,473 39280-123145497669632 ERROR: Failed when updating the huobi prices [in /Users/lgp/Desktop/python-workspace/demo/app/jobs.py:49]
Traceback (most recent call last):
  File "/Users/lgp/Desktop/python-workspace/demo/app/jobs.py", line 47, in huobi_update_prices
    kline_huobi()
NameError: global name 'kline_huobi' is not defined
2018-04-24 11:55:25,722 39280-123145497669632 ERROR: Failed when updating the huobi prices [in /Users/lgp/Desktop/python-workspace/demo/app/jobs.py:49]
Traceback (most recent call last):
  File "/Users/lgp/Desktop/python-workspace/demo/app/jobs.py", line 47, in huobi_update_prices
    kline_huobi()
NameError: global name 'kline_huobi' is not defined
2018-04-24 11:58:27,014 39315-123145490440192 ERROR: Failed when updating the huobi prices [in /Users/lgp/Desktop/python-workspace/demo/app/jobs.py:49]
Traceback (most recent call last):
  File "/Users/lgp/Desktop/python-workspace/demo/app/jobs.py", line 47, in huobi_update_prices
    app.views.blog.kline_huobi()
AttributeError: 'Flask' object has no attribute 'views'
2018-04-24 11:59:27,210 39315-123145490440192 ERROR: Failed when updating the huobi prices [in /Users/lgp/Desktop/python-workspace/demo/app/jobs.py:49]
Traceback (most recent call last):
  File "/Users/lgp/Desktop/python-workspace/demo/app/jobs.py", line 47, in huobi_update_prices
    app.views.blog.kline_huobi()
AttributeError: 'Flask' object has no attribute 'views'
2018-04-24 12:01:21,574 39337-123145467723776 ERROR: Failed when updating the huobi prices [in /Users/lgp/Desktop/python-workspace/demo/app/jobs.py:50]
Traceback (most recent call last):
  File "/Users/lgp/Desktop/python-workspace/demo/app/jobs.py", line 48, in huobi_update_prices
    app.views.blog.kline_huobi()
AttributeError: 'Flask' object has no attribute 'views'
2018-04-24 12:03:05,438 39353-123145542750208 ERROR: Failed when updating the huobi prices [in /Users/lgp/Desktop/python-workspace/demo/app/jobs.py:50]
Traceback (most recent call last):
  File "/Users/lgp/Desktop/python-workspace/demo/app/jobs.py", line 48, in huobi_update_prices
    kline_huobi()
NameError: global name 'kline_huobi' is not defined
2018-04-24 12:04:05,694 39353-123145542750208 ERROR: Failed when updating the huobi prices [in /Users/lgp/Desktop/python-workspace/demo/app/jobs.py:50]
Traceback (most recent call last):
  File "/Users/lgp/Desktop/python-workspace/demo/app/jobs.py", line 48, in huobi_update_prices
    kline_huobi()
NameError: global name 'kline_huobi' is not defined
2018-04-24 12:37:29,442 39502-123145518641152 ERROR: Failed when updating the huobi prices [in /Users/lgp/Desktop/python-workspace/demo/app/jobs.py:52]
Traceback (most recent call last):
  File "/Users/lgp/Desktop/python-workspace/demo/app/jobs.py", line 50, in huobi_update_prices
    kline_huobi(app)
  File "/Users/lgp/Desktop/python-workspace/demo/app/views/public.py", line 215, in kline_huobi
    return jsonify(success=True, message=_('Save the post successfully.'))
  File "/Users/lgp/Desktop/python-workspace/venv/lib/python2.7/site-packages/flask/json.py", line 251, in jsonify
    if current_app.config['JSONIFY_PRETTYPRINT_REGULAR'] and not request.is_xhr:
  File "/Users/lgp/Desktop/python-workspace/venv/lib/python2.7/site-packages/werkzeug/local.py", line 347, in __getattr__
    return getattr(self._get_current_object(), name)
  File "/Users/lgp/Desktop/python-workspace/venv/lib/python2.7/site-packages/werkzeug/local.py", line 306, in _get_current_object
    return self.__local()
  File "/Users/lgp/Desktop/python-workspace/venv/lib/python2.7/site-packages/flask/globals.py", line 51, in _find_app
    raise RuntimeError(_app_ctx_err_msg)
RuntimeError: Working outside of application context.

This typically means that you attempted to use functionality that needed
to interface with the current application object in a way.  To solve
this set up an application context with app.app_context().  See the
documentation for more information.
2018-04-24 12:38:00,285 39502-123145518641152 ERROR: Failed when updating the huobi prices [in /Users/lgp/Desktop/python-workspace/demo/app/jobs.py:52]
Traceback (most recent call last):
  File "/Users/lgp/Desktop/python-workspace/demo/app/jobs.py", line 50, in huobi_update_prices
    kline_huobi(app)
  File "/Users/lgp/Desktop/python-workspace/demo/app/views/public.py", line 215, in kline_huobi
    return jsonify(success=True, message=_('Save the post successfully.'))
  File "/Users/lgp/Desktop/python-workspace/venv/lib/python2.7/site-packages/flask/json.py", line 251, in jsonify
    if current_app.config['JSONIFY_PRETTYPRINT_REGULAR'] and not request.is_xhr:
  File "/Users/lgp/Desktop/python-workspace/venv/lib/python2.7/site-packages/werkzeug/local.py", line 347, in __getattr__
    return getattr(self._get_current_object(), name)
  File "/Users/lgp/Desktop/python-workspace/venv/lib/python2.7/site-packages/werkzeug/local.py", line 306, in _get_current_object
    return self.__local()
  File "/Users/lgp/Desktop/python-workspace/venv/lib/python2.7/site-packages/flask/globals.py", line 51, in _find_app
    raise RuntimeError(_app_ctx_err_msg)
RuntimeError: Working outside of application context.

This typically means that you attempted to use functionality that needed
to interface with the current application object in a way.  To solve
this set up an application context with app.app_context().  See the
documentation for more information.
2018-04-24 12:38:33,840 39502-123145518641152 ERROR: Failed when updating the huobi prices [in /Users/lgp/Desktop/python-workspace/demo/app/jobs.py:52]
Traceback (most recent call last):
  File "/Users/lgp/Desktop/python-workspace/demo/app/jobs.py", line 50, in huobi_update_prices
    kline_huobi(app)
  File "/Users/lgp/Desktop/python-workspace/demo/app/views/public.py", line 215, in kline_huobi
    return jsonify(success=True, message=_('Save the post successfully.'))
  File "/Users/lgp/Desktop/python-workspace/venv/lib/python2.7/site-packages/flask/json.py", line 251, in jsonify
    if current_app.config['JSONIFY_PRETTYPRINT_REGULAR'] and not request.is_xhr:
  File "/Users/lgp/Desktop/python-workspace/venv/lib/python2.7/site-packages/werkzeug/local.py", line 347, in __getattr__
    return getattr(self._get_current_object(), name)
  File "/Users/lgp/Desktop/python-workspace/venv/lib/python2.7/site-packages/werkzeug/local.py", line 306, in _get_current_object
    return self.__local()
  File "/Users/lgp/Desktop/python-workspace/venv/lib/python2.7/site-packages/flask/globals.py", line 51, in _find_app
    raise RuntimeError(_app_ctx_err_msg)
RuntimeError: Working outside of application context.

This typically means that you attempted to use functionality that needed
to interface with the current application object in a way.  To solve
this set up an application context with app.app_context().  See the
documentation for more information.
2018-04-24 12:39:04,489 39502-123145518641152 ERROR: Failed when updating the huobi prices [in /Users/lgp/Desktop/python-workspace/demo/app/jobs.py:52]
Traceback (most recent call last):
  File "/Users/lgp/Desktop/python-workspace/demo/app/jobs.py", line 50, in huobi_update_prices
    kline_huobi(app)
  File "/Users/lgp/Desktop/python-workspace/demo/app/views/public.py", line 215, in kline_huobi
    return jsonify(success=True, message=_('Save the post successfully.'))
  File "/Users/lgp/Desktop/python-workspace/venv/lib/python2.7/site-packages/flask/json.py", line 251, in jsonify
    if current_app.config['JSONIFY_PRETTYPRINT_REGULAR'] and not request.is_xhr:
  File "/Users/lgp/Desktop/python-workspace/venv/lib/python2.7/site-packages/werkzeug/local.py", line 347, in __getattr__
    return getattr(self._get_current_object(), name)
  File "/Users/lgp/Desktop/python-workspace/venv/lib/python2.7/site-packages/werkzeug/local.py", line 306, in _get_current_object
    return self.__local()
  File "/Users/lgp/Desktop/python-workspace/venv/lib/python2.7/site-packages/flask/globals.py", line 51, in _find_app
    raise RuntimeError(_app_ctx_err_msg)
RuntimeError: Working outside of application context.

This typically means that you attempted to use functionality that needed
to interface with the current application object in a way.  To solve
this set up an application context with app.app_context().  See the
documentation for more information.
2018-04-24 12:39:51,536 39517-123145557286912 ERROR: Failed when updating the huobi prices [in /Users/lgp/Desktop/python-workspace/demo/app/jobs.py:52]
Traceback (most recent call last):
  File "/Users/lgp/Desktop/python-workspace/demo/app/jobs.py", line 50, in huobi_update_prices
    kline_huobi(app)
  File "/Users/lgp/Desktop/python-workspace/demo/app/views/public.py", line 215, in kline_huobi
    return jsonify(success=True, message=_('Save the post successfully.'))
  File "/Users/lgp/Desktop/python-workspace/venv/lib/python2.7/site-packages/flask/json.py", line 251, in jsonify
    if current_app.config['JSONIFY_PRETTYPRINT_REGULAR'] and not request.is_xhr:
  File "/Users/lgp/Desktop/python-workspace/venv/lib/python2.7/site-packages/werkzeug/local.py", line 347, in __getattr__
    return getattr(self._get_current_object(), name)
  File "/Users/lgp/Desktop/python-workspace/venv/lib/python2.7/site-packages/werkzeug/local.py", line 306, in _get_current_object
    return self.__local()
  File "/Users/lgp/Desktop/python-workspace/venv/lib/python2.7/site-packages/flask/globals.py", line 51, in _find_app
    raise RuntimeError(_app_ctx_err_msg)
RuntimeError: Working outside of application context.

This typically means that you attempted to use functionality that needed
to interface with the current application object in a way.  To solve
this set up an application context with app.app_context().  See the
documentation for more information.
2018-04-24 12:40:22,365 39517-123145557286912 ERROR: Failed when updating the huobi prices [in /Users/lgp/Desktop/python-workspace/demo/app/jobs.py:52]
Traceback (most recent call last):
  File "/Users/lgp/Desktop/python-workspace/demo/app/jobs.py", line 50, in huobi_update_prices
    kline_huobi(app)
  File "/Users/lgp/Desktop/python-workspace/demo/app/views/public.py", line 215, in kline_huobi
    return jsonify(success=True, message=_('Save the post successfully.'))
  File "/Users/lgp/Desktop/python-workspace/venv/lib/python2.7/site-packages/flask/json.py", line 251, in jsonify
    if current_app.config['JSONIFY_PRETTYPRINT_REGULAR'] and not request.is_xhr:
  File "/Users/lgp/Desktop/python-workspace/venv/lib/python2.7/site-packages/werkzeug/local.py", line 347, in __getattr__
    return getattr(self._get_current_object(), name)
  File "/Users/lgp/Desktop/python-workspace/venv/lib/python2.7/site-packages/werkzeug/local.py", line 306, in _get_current_object
    return self.__local()
  File "/Users/lgp/Desktop/python-workspace/venv/lib/python2.7/site-packages/flask/globals.py", line 51, in _find_app
    raise RuntimeError(_app_ctx_err_msg)
RuntimeError: Working outside of application context.

This typically means that you attempted to use functionality that needed
to interface with the current application object in a way.  To solve
this set up an application context with app.app_context().  See the
documentation for more information.
2018-04-24 12:40:53,188 39517-123145557286912 ERROR: Failed when updating the huobi prices [in /Users/lgp/Desktop/python-workspace/demo/app/jobs.py:52]
Traceback (most recent call last):
  File "/Users/lgp/Desktop/python-workspace/demo/app/jobs.py", line 50, in huobi_update_prices
    kline_huobi(app)
  File "/Users/lgp/Desktop/python-workspace/demo/app/views/public.py", line 215, in kline_huobi
    return jsonify(success=True, message=_('Save the post successfully.'))
  File "/Users/lgp/Desktop/python-workspace/venv/lib/python2.7/site-packages/flask/json.py", line 251, in jsonify
    if current_app.config['JSONIFY_PRETTYPRINT_REGULAR'] and not request.is_xhr:
  File "/Users/lgp/Desktop/python-workspace/venv/lib/python2.7/site-packages/werkzeug/local.py", line 347, in __getattr__
    return getattr(self._get_current_object(), name)
  File "/Users/lgp/Desktop/python-workspace/venv/lib/python2.7/site-packages/werkzeug/local.py", line 306, in _get_current_object
    return self.__local()
  File "/Users/lgp/Desktop/python-workspace/venv/lib/python2.7/site-packages/flask/globals.py", line 51, in _find_app
    raise RuntimeError(_app_ctx_err_msg)
RuntimeError: Working outside of application context.

This typically means that you attempted to use functionality that needed
to interface with the current application object in a way.  To solve
this set up an application context with app.app_context().  See the
documentation for more information.
2018-04-24 12:41:23,630 39517-123145557286912 ERROR: Failed when updating the huobi prices [in /Users/lgp/Desktop/python-workspace/demo/app/jobs.py:52]
Traceback (most recent call last):
  File "/Users/lgp/Desktop/python-workspace/demo/app/jobs.py", line 50, in huobi_update_prices
    kline_huobi(app)
  File "/Users/lgp/Desktop/python-workspace/demo/app/views/public.py", line 215, in kline_huobi
    return jsonify(success=True, message=_('Save the post successfully.'))
  File "/Users/lgp/Desktop/python-workspace/venv/lib/python2.7/site-packages/flask/json.py", line 251, in jsonify
    if current_app.config['JSONIFY_PRETTYPRINT_REGULAR'] and not request.is_xhr:
  File "/Users/lgp/Desktop/python-workspace/venv/lib/python2.7/site-packages/werkzeug/local.py", line 347, in __getattr__
    return getattr(self._get_current_object(), name)
  File "/Users/lgp/Desktop/python-workspace/venv/lib/python2.7/site-packages/werkzeug/local.py", line 306, in _get_current_object
    return self.__local()
  File "/Users/lgp/Desktop/python-workspace/venv/lib/python2.7/site-packages/flask/globals.py", line 51, in _find_app
    raise RuntimeError(_app_ctx_err_msg)
RuntimeError: Working outside of application context.

This typically means that you attempted to use functionality that needed
to interface with the current application object in a way.  To solve
this set up an application context with app.app_context().  See the
documentation for more information.
2018-04-24 12:42:45,022 39544-123145406402560 ERROR: Failed when updating the huobi prices [in /Users/lgp/Desktop/python-workspace/demo/app/jobs.py:52]
Traceback (most recent call last):
  File "/Users/lgp/Desktop/python-workspace/demo/app/jobs.py", line 50, in huobi_update_prices
    kline_huobi(app)
  File "/Users/lgp/Desktop/python-workspace/demo/app/views/public.py", line 217, in kline_huobi
    return jsonify(success=True, message=_('Save the post successfully.'))
  File "/Users/lgp/Desktop/python-workspace/venv/lib/python2.7/site-packages/flask/json.py", line 251, in jsonify
    if current_app.config['JSONIFY_PRETTYPRINT_REGULAR'] and not request.is_xhr:
  File "/Users/lgp/Desktop/python-workspace/venv/lib/python2.7/site-packages/werkzeug/local.py", line 347, in __getattr__
    return getattr(self._get_current_object(), name)
  File "/Users/lgp/Desktop/python-workspace/venv/lib/python2.7/site-packages/werkzeug/local.py", line 306, in _get_current_object
    return self.__local()
  File "/Users/lgp/Desktop/python-workspace/venv/lib/python2.7/site-packages/flask/globals.py", line 51, in _find_app
    raise RuntimeError(_app_ctx_err_msg)
RuntimeError: Working outside of application context.

This typically means that you attempted to use functionality that needed
to interface with the current application object in a way.  To solve
this set up an application context with app.app_context().  See the
documentation for more information.
2018-04-24 12:43:15,743 39544-123145406402560 ERROR: Failed when updating the huobi prices [in /Users/lgp/Desktop/python-workspace/demo/app/jobs.py:52]
Traceback (most recent call last):
  File "/Users/lgp/Desktop/python-workspace/demo/app/jobs.py", line 50, in huobi_update_prices
    kline_huobi(app)
  File "/Users/lgp/Desktop/python-workspace/demo/app/views/public.py", line 217, in kline_huobi
    return jsonify(success=True, message=_('Save the post successfully.'))
  File "/Users/lgp/Desktop/python-workspace/venv/lib/python2.7/site-packages/flask/json.py", line 251, in jsonify
    if current_app.config['JSONIFY_PRETTYPRINT_REGULAR'] and not request.is_xhr:
  File "/Users/lgp/Desktop/python-workspace/venv/lib/python2.7/site-packages/werkzeug/local.py", line 347, in __getattr__
    return getattr(self._get_current_object(), name)
  File "/Users/lgp/Desktop/python-workspace/venv/lib/python2.7/site-packages/werkzeug/local.py", line 306, in _get_current_object
    return self.__local()
  File "/Users/lgp/Desktop/python-workspace/venv/lib/python2.7/site-packages/flask/globals.py", line 51, in _find_app
    raise RuntimeError(_app_ctx_err_msg)
RuntimeError: Working outside of application context.

This typically means that you attempted to use functionality that needed
to interface with the current application object in a way.  To solve
this set up an application context with app.app_context().  See the
documentation for more information.
2018-04-24 12:43:46,461 39544-123145406402560 ERROR: Failed when updating the huobi prices [in /Users/lgp/Desktop/python-workspace/demo/app/jobs.py:52]
Traceback (most recent call last):
  File "/Users/lgp/Desktop/python-workspace/demo/app/jobs.py", line 50, in huobi_update_prices
    kline_huobi(app)
  File "/Users/lgp/Desktop/python-workspace/demo/app/views/public.py", line 217, in kline_huobi
    return jsonify(success=True, message=_('Save the post successfully.'))
  File "/Users/lgp/Desktop/python-workspace/venv/lib/python2.7/site-packages/flask/json.py", line 251, in jsonify
    if current_app.config['JSONIFY_PRETTYPRINT_REGULAR'] and not request.is_xhr:
  File "/Users/lgp/Desktop/python-workspace/venv/lib/python2.7/site-packages/werkzeug/local.py", line 347, in __getattr__
    return getattr(self._get_current_object(), name)
  File "/Users/lgp/Desktop/python-workspace/venv/lib/python2.7/site-packages/werkzeug/local.py", line 306, in _get_current_object
    return self.__local()
  File "/Users/lgp/Desktop/python-workspace/venv/lib/python2.7/site-packages/flask/globals.py", line 51, in _find_app
    raise RuntimeError(_app_ctx_err_msg)
RuntimeError: Working outside of application context.

This typically means that you attempted to use functionality that needed
to interface with the current application object in a way.  To solve
this set up an application context with app.app_context().  See the
documentation for more information.
2018-04-24 12:44:17,181 39544-123145406402560 ERROR: Failed when updating the huobi prices [in /Users/lgp/Desktop/python-workspace/demo/app/jobs.py:52]
Traceback (most recent call last):
  File "/Users/lgp/Desktop/python-workspace/demo/app/jobs.py", line 50, in huobi_update_prices
    kline_huobi(app)
  File "/Users/lgp/Desktop/python-workspace/demo/app/views/public.py", line 217, in kline_huobi
    return jsonify(success=True, message=_('Save the post successfully.'))
  File "/Users/lgp/Desktop/python-workspace/venv/lib/python2.7/site-packages/flask/json.py", line 251, in jsonify
    if current_app.config['JSONIFY_PRETTYPRINT_REGULAR'] and not request.is_xhr:
  File "/Users/lgp/Desktop/python-workspace/venv/lib/python2.7/site-packages/werkzeug/local.py", line 347, in __getattr__
    return getattr(self._get_current_object(), name)
  File "/Users/lgp/Desktop/python-workspace/venv/lib/python2.7/site-packages/werkzeug/local.py", line 306, in _get_current_object
    return self.__local()
  File "/Users/lgp/Desktop/python-workspace/venv/lib/python2.7/site-packages/flask/globals.py", line 51, in _find_app
    raise RuntimeError(_app_ctx_err_msg)
RuntimeError: Working outside of application context.

This typically means that you attempted to use functionality that needed
to interface with the current application object in a way.  To solve
this set up an application context with app.app_context().  See the
documentation for more information.
2018-04-24 12:44:47,647 39544-123145406402560 ERROR: Failed when updating the huobi prices [in /Users/lgp/Desktop/python-workspace/demo/app/jobs.py:52]
Traceback (most recent call last):
  File "/Users/lgp/Desktop/python-workspace/demo/app/jobs.py", line 50, in huobi_update_prices
    kline_huobi(app)
  File "/Users/lgp/Desktop/python-workspace/demo/app/views/public.py", line 217, in kline_huobi
    return jsonify(success=True, message=_('Save the post successfully.'))
  File "/Users/lgp/Desktop/python-workspace/venv/lib/python2.7/site-packages/flask/json.py", line 251, in jsonify
    if current_app.config['JSONIFY_PRETTYPRINT_REGULAR'] and not request.is_xhr:
  File "/Users/lgp/Desktop/python-workspace/venv/lib/python2.7/site-packages/werkzeug/local.py", line 347, in __getattr__
    return getattr(self._get_current_object(), name)
  File "/Users/lgp/Desktop/python-workspace/venv/lib/python2.7/site-packages/werkzeug/local.py", line 306, in _get_current_object
    return self.__local()
  File "/Users/lgp/Desktop/python-workspace/venv/lib/python2.7/site-packages/flask/globals.py", line 51, in _find_app
    raise RuntimeError(_app_ctx_err_msg)
RuntimeError: Working outside of application context.

This typically means that you attempted to use functionality that needed
to interface with the current application object in a way.  To solve
this set up an application context with app.app_context().  See the
documentation for more information.
2018-04-24 12:45:18,415 39544-123145406402560 ERROR: Failed when updating the huobi prices [in /Users/lgp/Desktop/python-workspace/demo/app/jobs.py:52]
Traceback (most recent call last):
  File "/Users/lgp/Desktop/python-workspace/demo/app/jobs.py", line 50, in huobi_update_prices
    kline_huobi(app)
  File "/Users/lgp/Desktop/python-workspace/demo/app/views/public.py", line 217, in kline_huobi
    return jsonify(success=True, message=_('Save the post successfully.'))
  File "/Users/lgp/Desktop/python-workspace/venv/lib/python2.7/site-packages/flask/json.py", line 251, in jsonify
    if current_app.config['JSONIFY_PRETTYPRINT_REGULAR'] and not request.is_xhr:
  File "/Users/lgp/Desktop/python-workspace/venv/lib/python2.7/site-packages/werkzeug/local.py", line 347, in __getattr__
    return getattr(self._get_current_object(), name)
  File "/Users/lgp/Desktop/python-workspace/venv/lib/python2.7/site-packages/werkzeug/local.py", line 306, in _get_current_object
    return self.__local()
  File "/Users/lgp/Desktop/python-workspace/venv/lib/python2.7/site-packages/flask/globals.py", line 51, in _find_app
    raise RuntimeError(_app_ctx_err_msg)
RuntimeError: Working outside of application context.

This typically means that you attempted to use functionality that needed
to interface with the current application object in a way.  To solve
this set up an application context with app.app_context().  See the
documentation for more information.
2018-04-24 14:30:54,992 39707-123145543581696 ERROR: Failed when updating the huobi prices [in /Users/lgp/Desktop/python-workspace/demo/app/jobs.py:52]
Traceback (most recent call last):
  File "/Users/lgp/Desktop/python-workspace/demo/app/jobs.py", line 50, in huobi_update_prices
    kline_huobi(app)
  File "/Users/lgp/Desktop/python-workspace/demo/app/views/public.py", line 217, in kline_huobi
    return jsonify(success=True, message=_('Save the post successfully.'))
  File "/Users/lgp/Desktop/python-workspace/venv/lib/python2.7/site-packages/flask/json.py", line 251, in jsonify
    if current_app.config['JSONIFY_PRETTYPRINT_REGULAR'] and not request.is_xhr:
  File "/Users/lgp/Desktop/python-workspace/venv/lib/python2.7/site-packages/werkzeug/local.py", line 347, in __getattr__
    return getattr(self._get_current_object(), name)
  File "/Users/lgp/Desktop/python-workspace/venv/lib/python2.7/site-packages/werkzeug/local.py", line 306, in _get_current_object
    return self.__local()
  File "/Users/lgp/Desktop/python-workspace/venv/lib/python2.7/site-packages/flask/globals.py", line 51, in _find_app
    raise RuntimeError(_app_ctx_err_msg)
RuntimeError: Working outside of application context.

This typically means that you attempted to use functionality that needed
to interface with the current application object in a way.  To solve
this set up an application context with app.app_context().  See the
documentation for more information.
2018-04-24 14:31:25,444 39707-123145543581696 ERROR: Failed when updating the huobi prices [in /Users/lgp/Desktop/python-workspace/demo/app/jobs.py:52]
Traceback (most recent call last):
  File "/Users/lgp/Desktop/python-workspace/demo/app/jobs.py", line 50, in huobi_update_prices
    kline_huobi(app)
  File "/Users/lgp/Desktop/python-workspace/demo/app/views/public.py", line 217, in kline_huobi
    return jsonify(success=True, message=_('Save the post successfully.'))
  File "/Users/lgp/Desktop/python-workspace/venv/lib/python2.7/site-packages/flask/json.py", line 251, in jsonify
    if current_app.config['JSONIFY_PRETTYPRINT_REGULAR'] and not request.is_xhr:
  File "/Users/lgp/Desktop/python-workspace/venv/lib/python2.7/site-packages/werkzeug/local.py", line 347, in __getattr__
    return getattr(self._get_current_object(), name)
  File "/Users/lgp/Desktop/python-workspace/venv/lib/python2.7/site-packages/werkzeug/local.py", line 306, in _get_current_object
    return self.__local()
  File "/Users/lgp/Desktop/python-workspace/venv/lib/python2.7/site-packages/flask/globals.py", line 51, in _find_app
    raise RuntimeError(_app_ctx_err_msg)
RuntimeError: Working outside of application context.

This typically means that you attempted to use functionality that needed
to interface with the current application object in a way.  To solve
this set up an application context with app.app_context().  See the
documentation for more information.
2018-04-24 14:31:56,161 39707-123145543581696 ERROR: Failed when updating the huobi prices [in /Users/lgp/Desktop/python-workspace/demo/app/jobs.py:52]
Traceback (most recent call last):
  File "/Users/lgp/Desktop/python-workspace/demo/app/jobs.py", line 50, in huobi_update_prices
    kline_huobi(app)
  File "/Users/lgp/Desktop/python-workspace/demo/app/views/public.py", line 217, in kline_huobi
    return jsonify(success=True, message=_('Save the post successfully.'))
  File "/Users/lgp/Desktop/python-workspace/venv/lib/python2.7/site-packages/flask/json.py", line 251, in jsonify
    if current_app.config['JSONIFY_PRETTYPRINT_REGULAR'] and not request.is_xhr:
  File "/Users/lgp/Desktop/python-workspace/venv/lib/python2.7/site-packages/werkzeug/local.py", line 347, in __getattr__
    return getattr(self._get_current_object(), name)
  File "/Users/lgp/Desktop/python-workspace/venv/lib/python2.7/site-packages/werkzeug/local.py", line 306, in _get_current_object
    return self.__local()
  File "/Users/lgp/Desktop/python-workspace/venv/lib/python2.7/site-packages/flask/globals.py", line 51, in _find_app
    raise RuntimeError(_app_ctx_err_msg)
RuntimeError: Working outside of application context.

This typically means that you attempted to use functionality that needed
to interface with the current application object in a way.  To solve
this set up an application context with app.app_context().  See the
documentation for more information.
2018-04-24 14:32:26,845 39707-123145543581696 ERROR: Failed when updating the huobi prices [in /Users/lgp/Desktop/python-workspace/demo/app/jobs.py:52]
Traceback (most recent call last):
  File "/Users/lgp/Desktop/python-workspace/demo/app/jobs.py", line 50, in huobi_update_prices
    kline_huobi(app)
  File "/Users/lgp/Desktop/python-workspace/demo/app/views/public.py", line 217, in kline_huobi
    return jsonify(success=True, message=_('Save the post successfully.'))
  File "/Users/lgp/Desktop/python-workspace/venv/lib/python2.7/site-packages/flask/json.py", line 251, in jsonify
    if current_app.config['JSONIFY_PRETTYPRINT_REGULAR'] and not request.is_xhr:
  File "/Users/lgp/Desktop/python-workspace/venv/lib/python2.7/site-packages/werkzeug/local.py", line 347, in __getattr__
    return getattr(self._get_current_object(), name)
  File "/Users/lgp/Desktop/python-workspace/venv/lib/python2.7/site-packages/werkzeug/local.py", line 306, in _get_current_object
    return self.__local()
  File "/Users/lgp/Desktop/python-workspace/venv/lib/python2.7/site-packages/flask/globals.py", line 51, in _find_app
    raise RuntimeError(_app_ctx_err_msg)
RuntimeError: Working outside of application context.

This typically means that you attempted to use functionality that needed
to interface with the current application object in a way.  To solve
this set up an application context with app.app_context().  See the
documentation for more information.
2018-04-24 14:32:57,574 39707-123145543581696 ERROR: Failed when updating the huobi prices [in /Users/lgp/Desktop/python-workspace/demo/app/jobs.py:52]
Traceback (most recent call last):
  File "/Users/lgp/Desktop/python-workspace/demo/app/jobs.py", line 50, in huobi_update_prices
    kline_huobi(app)
  File "/Users/lgp/Desktop/python-workspace/demo/app/views/public.py", line 217, in kline_huobi
    return jsonify(success=True, message=_('Save the post successfully.'))
  File "/Users/lgp/Desktop/python-workspace/venv/lib/python2.7/site-packages/flask/json.py", line 251, in jsonify
    if current_app.config['JSONIFY_PRETTYPRINT_REGULAR'] and not request.is_xhr:
  File "/Users/lgp/Desktop/python-workspace/venv/lib/python2.7/site-packages/werkzeug/local.py", line 347, in __getattr__
    return getattr(self._get_current_object(), name)
  File "/Users/lgp/Desktop/python-workspace/venv/lib/python2.7/site-packages/werkzeug/local.py", line 306, in _get_current_object
    return self.__local()
  File "/Users/lgp/Desktop/python-workspace/venv/lib/python2.7/site-packages/flask/globals.py", line 51, in _find_app
    raise RuntimeError(_app_ctx_err_msg)
RuntimeError: Working outside of application context.

This typically means that you attempted to use functionality that needed
to interface with the current application object in a way.  To solve
this set up an application context with app.app_context().  See the
documentation for more information.
2018-04-24 14:33:33,050 39728-123145414512640 ERROR: Failed when updating the huobi prices [in /Users/lgp/Desktop/python-workspace/demo/app/jobs.py:52]
Traceback (most recent call last):
  File "/Users/lgp/Desktop/python-workspace/demo/app/jobs.py", line 50, in huobi_update_prices
    kline_huobi(app)
  File "/Users/lgp/Desktop/python-workspace/demo/app/views/public.py", line 218, in kline_huobi
    return jsonify(success=True, message=_('Save the post successfully.'))
  File "/Users/lgp/Desktop/python-workspace/venv/lib/python2.7/site-packages/flask/json.py", line 251, in jsonify
    if current_app.config['JSONIFY_PRETTYPRINT_REGULAR'] and not request.is_xhr:
  File "/Users/lgp/Desktop/python-workspace/venv/lib/python2.7/site-packages/werkzeug/local.py", line 347, in __getattr__
    return getattr(self._get_current_object(), name)
  File "/Users/lgp/Desktop/python-workspace/venv/lib/python2.7/site-packages/werkzeug/local.py", line 306, in _get_current_object
    return self.__local()
  File "/Users/lgp/Desktop/python-workspace/venv/lib/python2.7/site-packages/flask/globals.py", line 51, in _find_app
    raise RuntimeError(_app_ctx_err_msg)
RuntimeError: Working outside of application context.

This typically means that you attempted to use functionality that needed
to interface with the current application object in a way.  To solve
this set up an application context with app.app_context().  See the
documentation for more information.
2018-04-24 14:34:03,457 39728-123145414512640 ERROR: Failed when updating the huobi prices [in /Users/lgp/Desktop/python-workspace/demo/app/jobs.py:52]
Traceback (most recent call last):
  File "/Users/lgp/Desktop/python-workspace/demo/app/jobs.py", line 50, in huobi_update_prices
    kline_huobi(app)
  File "/Users/lgp/Desktop/python-workspace/demo/app/views/public.py", line 218, in kline_huobi
    return jsonify(success=True, message=_('Save the post successfully.'))
  File "/Users/lgp/Desktop/python-workspace/venv/lib/python2.7/site-packages/flask/json.py", line 251, in jsonify
    if current_app.config['JSONIFY_PRETTYPRINT_REGULAR'] and not request.is_xhr:
  File "/Users/lgp/Desktop/python-workspace/venv/lib/python2.7/site-packages/werkzeug/local.py", line 347, in __getattr__
    return getattr(self._get_current_object(), name)
  File "/Users/lgp/Desktop/python-workspace/venv/lib/python2.7/site-packages/werkzeug/local.py", line 306, in _get_current_object
    return self.__local()
  File "/Users/lgp/Desktop/python-workspace/venv/lib/python2.7/site-packages/flask/globals.py", line 51, in _find_app
    raise RuntimeError(_app_ctx_err_msg)
RuntimeError: Working outside of application context.

This typically means that you attempted to use functionality that needed
to interface with the current application object in a way.  To solve
this set up an application context with app.app_context().  See the
documentation for more information.
2018-04-24 14:34:34,328 39728-123145414512640 ERROR: Failed when updating the huobi prices [in /Users/lgp/Desktop/python-workspace/demo/app/jobs.py:52]
Traceback (most recent call last):
  File "/Users/lgp/Desktop/python-workspace/demo/app/jobs.py", line 50, in huobi_update_prices
    kline_huobi(app)
  File "/Users/lgp/Desktop/python-workspace/demo/app/views/public.py", line 218, in kline_huobi
    return jsonify(success=True, message=_('Save the post successfully.'))
  File "/Users/lgp/Desktop/python-workspace/venv/lib/python2.7/site-packages/flask/json.py", line 251, in jsonify
    if current_app.config['JSONIFY_PRETTYPRINT_REGULAR'] and not request.is_xhr:
  File "/Users/lgp/Desktop/python-workspace/venv/lib/python2.7/site-packages/werkzeug/local.py", line 347, in __getattr__
    return getattr(self._get_current_object(), name)
  File "/Users/lgp/Desktop/python-workspace/venv/lib/python2.7/site-packages/werkzeug/local.py", line 306, in _get_current_object
    return self.__local()
  File "/Users/lgp/Desktop/python-workspace/venv/lib/python2.7/site-packages/flask/globals.py", line 51, in _find_app
    raise RuntimeError(_app_ctx_err_msg)
RuntimeError: Working outside of application context.

This typically means that you attempted to use functionality that needed
to interface with the current application object in a way.  To solve
this set up an application context with app.app_context().  See the
documentation for more information.
2018-04-24 14:35:04,722 39728-123145414512640 ERROR: Failed when updating the huobi prices [in /Users/lgp/Desktop/python-workspace/demo/app/jobs.py:52]
Traceback (most recent call last):
  File "/Users/lgp/Desktop/python-workspace/demo/app/jobs.py", line 50, in huobi_update_prices
    kline_huobi(app)
  File "/Users/lgp/Desktop/python-workspace/demo/app/views/public.py", line 218, in kline_huobi
    return jsonify(success=True, message=_('Save the post successfully.'))
  File "/Users/lgp/Desktop/python-workspace/venv/lib/python2.7/site-packages/flask/json.py", line 251, in jsonify
    if current_app.config['JSONIFY_PRETTYPRINT_REGULAR'] and not request.is_xhr:
  File "/Users/lgp/Desktop/python-workspace/venv/lib/python2.7/site-packages/werkzeug/local.py", line 347, in __getattr__
    return getattr(self._get_current_object(), name)
  File "/Users/lgp/Desktop/python-workspace/venv/lib/python2.7/site-packages/werkzeug/local.py", line 306, in _get_current_object
    return self.__local()
  File "/Users/lgp/Desktop/python-workspace/venv/lib/python2.7/site-packages/flask/globals.py", line 51, in _find_app
    raise RuntimeError(_app_ctx_err_msg)
RuntimeError: Working outside of application context.

This typically means that you attempted to use functionality that needed
to interface with the current application object in a way.  To solve
this set up an application context with app.app_context().  See the
documentation for more information.
2018-04-24 14:35:35,268 39728-123145414512640 ERROR: Failed when updating the huobi prices [in /Users/lgp/Desktop/python-workspace/demo/app/jobs.py:52]
Traceback (most recent call last):
  File "/Users/lgp/Desktop/python-workspace/demo/app/jobs.py", line 50, in huobi_update_prices
    kline_huobi(app)
  File "/Users/lgp/Desktop/python-workspace/demo/app/views/public.py", line 218, in kline_huobi
    return jsonify(success=True, message=_('Save the post successfully.'))
  File "/Users/lgp/Desktop/python-workspace/venv/lib/python2.7/site-packages/flask/json.py", line 251, in jsonify
    if current_app.config['JSONIFY_PRETTYPRINT_REGULAR'] and not request.is_xhr:
  File "/Users/lgp/Desktop/python-workspace/venv/lib/python2.7/site-packages/werkzeug/local.py", line 347, in __getattr__
    return getattr(self._get_current_object(), name)
  File "/Users/lgp/Desktop/python-workspace/venv/lib/python2.7/site-packages/werkzeug/local.py", line 306, in _get_current_object
    return self.__local()
  File "/Users/lgp/Desktop/python-workspace/venv/lib/python2.7/site-packages/flask/globals.py", line 51, in _find_app
    raise RuntimeError(_app_ctx_err_msg)
RuntimeError: Working outside of application context.

This typically means that you attempted to use functionality that needed
to interface with the current application object in a way.  To solve
this set up an application context with app.app_context().  See the
documentation for more information.
2018-04-24 14:36:49,912 39752-123145338384384 ERROR: Failed when updating the huobi prices [in /Users/lgp/Desktop/python-workspace/demo/app/jobs.py:52]
Traceback (most recent call last):
  File "/Users/lgp/Desktop/python-workspace/demo/app/jobs.py", line 50, in huobi_update_prices
    kline_huobi(app)
  File "/Users/lgp/Desktop/python-workspace/demo/app/views/public.py", line 218, in kline_huobi
    return jsonify(success=True, message='Save the post successfully.')
  File "/Users/lgp/Desktop/python-workspace/venv/lib/python2.7/site-packages/flask/json.py", line 251, in jsonify
    if current_app.config['JSONIFY_PRETTYPRINT_REGULAR'] and not request.is_xhr:
  File "/Users/lgp/Desktop/python-workspace/venv/lib/python2.7/site-packages/werkzeug/local.py", line 347, in __getattr__
    return getattr(self._get_current_object(), name)
  File "/Users/lgp/Desktop/python-workspace/venv/lib/python2.7/site-packages/werkzeug/local.py", line 306, in _get_current_object
    return self.__local()
  File "/Users/lgp/Desktop/python-workspace/venv/lib/python2.7/site-packages/flask/globals.py", line 51, in _find_app
    raise RuntimeError(_app_ctx_err_msg)
RuntimeError: Working outside of application context.

This typically means that you attempted to use functionality that needed
to interface with the current application object in a way.  To solve
this set up an application context with app.app_context().  See the
documentation for more information.
2018-04-24 14:37:20,625 39752-123145338384384 ERROR: Failed when updating the huobi prices [in /Users/lgp/Desktop/python-workspace/demo/app/jobs.py:52]
Traceback (most recent call last):
  File "/Users/lgp/Desktop/python-workspace/demo/app/jobs.py", line 50, in huobi_update_prices
    kline_huobi(app)
  File "/Users/lgp/Desktop/python-workspace/demo/app/views/public.py", line 218, in kline_huobi
    return jsonify(success=True, message='Save the post successfully.')
  File "/Users/lgp/Desktop/python-workspace/venv/lib/python2.7/site-packages/flask/json.py", line 251, in jsonify
    if current_app.config['JSONIFY_PRETTYPRINT_REGULAR'] and not request.is_xhr:
  File "/Users/lgp/Desktop/python-workspace/venv/lib/python2.7/site-packages/werkzeug/local.py", line 347, in __getattr__
    return getattr(self._get_current_object(), name)
  File "/Users/lgp/Desktop/python-workspace/venv/lib/python2.7/site-packages/werkzeug/local.py", line 306, in _get_current_object
    return self.__local()
  File "/Users/lgp/Desktop/python-workspace/venv/lib/python2.7/site-packages/flask/globals.py", line 51, in _find_app
    raise RuntimeError(_app_ctx_err_msg)
RuntimeError: Working outside of application context.

This typically means that you attempted to use functionality that needed
to interface with the current application object in a way.  To solve
this set up an application context with app.app_context().  See the
documentation for more information.
2018-04-24 14:38:10,803 39763-123145575444480 ERROR: Failed when updating the huobi prices [in /Users/lgp/Desktop/python-workspace/demo/app/jobs.py:52]
Traceback (most recent call last):
  File "/Users/lgp/Desktop/python-workspace/demo/app/jobs.py", line 50, in huobi_update_prices
    kline_huobi(app)
  File "/Users/lgp/Desktop/python-workspace/demo/app/views/public.py", line 218, in kline_huobi
    return jsonify(success=True, message=_('Save the post successfully.'))
  File "/Users/lgp/Desktop/python-workspace/venv/lib/python2.7/site-packages/flask/json.py", line 251, in jsonify
    if current_app.config['JSONIFY_PRETTYPRINT_REGULAR'] and not request.is_xhr:
  File "/Users/lgp/Desktop/python-workspace/venv/lib/python2.7/site-packages/werkzeug/local.py", line 347, in __getattr__
    return getattr(self._get_current_object(), name)
  File "/Users/lgp/Desktop/python-workspace/venv/lib/python2.7/site-packages/werkzeug/local.py", line 306, in _get_current_object
    return self.__local()
  File "/Users/lgp/Desktop/python-workspace/venv/lib/python2.7/site-packages/flask/globals.py", line 51, in _find_app
    raise RuntimeError(_app_ctx_err_msg)
RuntimeError: Working outside of application context.

This typically means that you attempted to use functionality that needed
to interface with the current application object in a way.  To solve
this set up an application context with app.app_context().  See the
documentation for more information.
2018-04-24 14:38:41,165 39763-123145575444480 ERROR: Failed when updating the huobi prices [in /Users/lgp/Desktop/python-workspace/demo/app/jobs.py:52]
Traceback (most recent call last):
  File "/Users/lgp/Desktop/python-workspace/demo/app/jobs.py", line 50, in huobi_update_prices
    kline_huobi(app)
  File "/Users/lgp/Desktop/python-workspace/demo/app/views/public.py", line 218, in kline_huobi
    return jsonify(success=True, message=_('Save the post successfully.'))
  File "/Users/lgp/Desktop/python-workspace/venv/lib/python2.7/site-packages/flask/json.py", line 251, in jsonify
    if current_app.config['JSONIFY_PRETTYPRINT_REGULAR'] and not request.is_xhr:
  File "/Users/lgp/Desktop/python-workspace/venv/lib/python2.7/site-packages/werkzeug/local.py", line 347, in __getattr__
    return getattr(self._get_current_object(), name)
  File "/Users/lgp/Desktop/python-workspace/venv/lib/python2.7/site-packages/werkzeug/local.py", line 306, in _get_current_object
    return self.__local()
  File "/Users/lgp/Desktop/python-workspace/venv/lib/python2.7/site-packages/flask/globals.py", line 51, in _find_app
    raise RuntimeError(_app_ctx_err_msg)
RuntimeError: Working outside of application context.

This typically means that you attempted to use functionality that needed
to interface with the current application object in a way.  To solve
this set up an application context with app.app_context().  See the
documentation for more information.
2018-04-24 14:39:11,832 39763-123145575444480 ERROR: Failed when updating the huobi prices [in /Users/lgp/Desktop/python-workspace/demo/app/jobs.py:52]
Traceback (most recent call last):
  File "/Users/lgp/Desktop/python-workspace/demo/app/jobs.py", line 50, in huobi_update_prices
    kline_huobi(app)
  File "/Users/lgp/Desktop/python-workspace/demo/app/views/public.py", line 218, in kline_huobi
    return jsonify(success=True, message=_('Save the post successfully.'))
  File "/Users/lgp/Desktop/python-workspace/venv/lib/python2.7/site-packages/flask/json.py", line 251, in jsonify
    if current_app.config['JSONIFY_PRETTYPRINT_REGULAR'] and not request.is_xhr:
  File "/Users/lgp/Desktop/python-workspace/venv/lib/python2.7/site-packages/werkzeug/local.py", line 347, in __getattr__
    return getattr(self._get_current_object(), name)
  File "/Users/lgp/Desktop/python-workspace/venv/lib/python2.7/site-packages/werkzeug/local.py", line 306, in _get_current_object
    return self.__local()
  File "/Users/lgp/Desktop/python-workspace/venv/lib/python2.7/site-packages/flask/globals.py", line 51, in _find_app
    raise RuntimeError(_app_ctx_err_msg)
RuntimeError: Working outside of application context.

This typically means that you attempted to use functionality that needed
to interface with the current application object in a way.  To solve
this set up an application context with app.app_context().  See the
documentation for more information.
2018-04-24 14:39:42,222 39763-123145575444480 ERROR: Failed when updating the huobi prices [in /Users/lgp/Desktop/python-workspace/demo/app/jobs.py:52]
Traceback (most recent call last):
  File "/Users/lgp/Desktop/python-workspace/demo/app/jobs.py", line 50, in huobi_update_prices
    kline_huobi(app)
  File "/Users/lgp/Desktop/python-workspace/demo/app/views/public.py", line 218, in kline_huobi
    return jsonify(success=True, message=_('Save the post successfully.'))
  File "/Users/lgp/Desktop/python-workspace/venv/lib/python2.7/site-packages/flask/json.py", line 251, in jsonify
    if current_app.config['JSONIFY_PRETTYPRINT_REGULAR'] and not request.is_xhr:
  File "/Users/lgp/Desktop/python-workspace/venv/lib/python2.7/site-packages/werkzeug/local.py", line 347, in __getattr__
    return getattr(self._get_current_object(), name)
  File "/Users/lgp/Desktop/python-workspace/venv/lib/python2.7/site-packages/werkzeug/local.py", line 306, in _get_current_object
    return self.__local()
  File "/Users/lgp/Desktop/python-workspace/venv/lib/python2.7/site-packages/flask/globals.py", line 51, in _find_app
    raise RuntimeError(_app_ctx_err_msg)
RuntimeError: Working outside of application context.

This typically means that you attempted to use functionality that needed
to interface with the current application object in a way.  To solve
this set up an application context with app.app_context().  See the
documentation for more information.
2018-04-24 14:40:12,757 39763-123145575444480 ERROR: Failed when updating the huobi prices [in /Users/lgp/Desktop/python-workspace/demo/app/jobs.py:52]
Traceback (most recent call last):
  File "/Users/lgp/Desktop/python-workspace/demo/app/jobs.py", line 50, in huobi_update_prices
    kline_huobi(app)
  File "/Users/lgp/Desktop/python-workspace/demo/app/views/public.py", line 218, in kline_huobi
    return jsonify(success=True, message=_('Save the post successfully.'))
  File "/Users/lgp/Desktop/python-workspace/venv/lib/python2.7/site-packages/flask/json.py", line 251, in jsonify
    if current_app.config['JSONIFY_PRETTYPRINT_REGULAR'] and not request.is_xhr:
  File "/Users/lgp/Desktop/python-workspace/venv/lib/python2.7/site-packages/werkzeug/local.py", line 347, in __getattr__
    return getattr(self._get_current_object(), name)
  File "/Users/lgp/Desktop/python-workspace/venv/lib/python2.7/site-packages/werkzeug/local.py", line 306, in _get_current_object
    return self.__local()
  File "/Users/lgp/Desktop/python-workspace/venv/lib/python2.7/site-packages/flask/globals.py", line 51, in _find_app
    raise RuntimeError(_app_ctx_err_msg)
RuntimeError: Working outside of application context.

This typically means that you attempted to use functionality that needed
to interface with the current application object in a way.  To solve
this set up an application context with app.app_context().  See the
documentation for more information.
2018-04-24 14:40:43,378 39763-123145575444480 ERROR: Failed when updating the huobi prices [in /Users/lgp/Desktop/python-workspace/demo/app/jobs.py:52]
Traceback (most recent call last):
  File "/Users/lgp/Desktop/python-workspace/demo/app/jobs.py", line 50, in huobi_update_prices
    kline_huobi(app)
  File "/Users/lgp/Desktop/python-workspace/demo/app/views/public.py", line 218, in kline_huobi
    return jsonify(success=True, message=_('Save the post successfully.'))
  File "/Users/lgp/Desktop/python-workspace/venv/lib/python2.7/site-packages/flask/json.py", line 251, in jsonify
    if current_app.config['JSONIFY_PRETTYPRINT_REGULAR'] and not request.is_xhr:
  File "/Users/lgp/Desktop/python-workspace/venv/lib/python2.7/site-packages/werkzeug/local.py", line 347, in __getattr__
    return getattr(self._get_current_object(), name)
  File "/Users/lgp/Desktop/python-workspace/venv/lib/python2.7/site-packages/werkzeug/local.py", line 306, in _get_current_object
    return self.__local()
  File "/Users/lgp/Desktop/python-workspace/venv/lib/python2.7/site-packages/flask/globals.py", line 51, in _find_app
    raise RuntimeError(_app_ctx_err_msg)
RuntimeError: Working outside of application context.

This typically means that you attempted to use functionality that needed
to interface with the current application object in a way.  To solve
this set up an application context with app.app_context().  See the
documentation for more information.
2018-04-24 14:41:13,761 39763-123145575444480 ERROR: Failed when updating the huobi prices [in /Users/lgp/Desktop/python-workspace/demo/app/jobs.py:52]
Traceback (most recent call last):
  File "/Users/lgp/Desktop/python-workspace/demo/app/jobs.py", line 50, in huobi_update_prices
    kline_huobi(app)
  File "/Users/lgp/Desktop/python-workspace/demo/app/views/public.py", line 218, in kline_huobi
    return jsonify(success=True, message=_('Save the post successfully.'))
  File "/Users/lgp/Desktop/python-workspace/venv/lib/python2.7/site-packages/flask/json.py", line 251, in jsonify
    if current_app.config['JSONIFY_PRETTYPRINT_REGULAR'] and not request.is_xhr:
  File "/Users/lgp/Desktop/python-workspace/venv/lib/python2.7/site-packages/werkzeug/local.py", line 347, in __getattr__
    return getattr(self._get_current_object(), name)
  File "/Users/lgp/Desktop/python-workspace/venv/lib/python2.7/site-packages/werkzeug/local.py", line 306, in _get_current_object
    return self.__local()
  File "/Users/lgp/Desktop/python-workspace/venv/lib/python2.7/site-packages/flask/globals.py", line 51, in _find_app
    raise RuntimeError(_app_ctx_err_msg)
RuntimeError: Working outside of application context.

This typically means that you attempted to use functionality that needed
to interface with the current application object in a way.  To solve
this set up an application context with app.app_context().  See the
documentation for more information.
2018-04-24 15:04:01,955 39777-123145547587584 ERROR: Failed when updating the huobi prices [in /Users/lgp/Desktop/python-workspace/demo/app/jobs.py:52]
Traceback (most recent call last):
  File "/Users/lgp/Desktop/python-workspace/demo/app/jobs.py", line 50, in huobi_update_prices
    kline_huobi(app)
  File "/Users/lgp/Desktop/python-workspace/demo/app/views/public.py", line 201, in kline_huobi
    datas = byteify(udata)['data']  # 将unicode的key和value转为string
KeyError: 'data'
2018-04-24 15:37:54,151 39777-123145547587584 ERROR: Failed when updating the huobi prices [in /Users/lgp/Desktop/python-workspace/demo/app/jobs.py:52]
Traceback (most recent call last):
  File "/Users/lgp/Desktop/python-workspace/demo/app/jobs.py", line 50, in huobi_update_prices
    kline_huobi(app)
  File "/Users/lgp/Desktop/python-workspace/demo/app/views/public.py", line 201, in kline_huobi
    datas = byteify(udata)['data']  # 将unicode的key和value转为string
KeyError: 'data'
2018-04-24 16:17:50,153 39777-123145547587584 ERROR: Failed when updating the huobi prices [in /Users/lgp/Desktop/python-workspace/demo/app/jobs.py:52]
Traceback (most recent call last):
  File "/Users/lgp/Desktop/python-workspace/demo/app/jobs.py", line 50, in huobi_update_prices
    kline_huobi(app)
  File "/Users/lgp/Desktop/python-workspace/demo/app/views/public.py", line 201, in kline_huobi
    datas = byteify(udata)['data']  # 将unicode的key和value转为string
KeyError: 'data'
2018-04-24 16:20:37,019 39777-123145547587584 ERROR: Failed when updating the huobi prices [in /Users/lgp/Desktop/python-workspace/demo/app/jobs.py:52]
Traceback (most recent call last):
  File "/Users/lgp/Desktop/python-workspace/demo/app/jobs.py", line 50, in huobi_update_prices
    kline_huobi(app)
  File "/Users/lgp/Desktop/python-workspace/demo/app/views/public.py", line 201, in kline_huobi
    datas = byteify(udata)['data']  # 将unicode的key和value转为string
KeyError: 'data'
2018-04-24 16:35:44,030 39777-123145547587584 ERROR: Failed when updating the huobi prices [in /Users/lgp/Desktop/python-workspace/demo/app/jobs.py:52]
Traceback (most recent call last):
  File "/Users/lgp/Desktop/python-workspace/demo/app/jobs.py", line 50, in huobi_update_prices
    kline_huobi(app)
  File "/Users/lgp/Desktop/python-workspace/demo/app/views/public.py", line 201, in kline_huobi
    datas = byteify(udata)['data']  # 将unicode的key和value转为string
KeyError: 'data'
2018-04-24 17:21:42,173 39777-123145547587584 ERROR: Failed when updating the huobi prices [in /Users/lgp/Desktop/python-workspace/demo/app/jobs.py:52]
Traceback (most recent call last):
  File "/Users/lgp/Desktop/python-workspace/demo/app/jobs.py", line 50, in huobi_update_prices
    kline_huobi(app)
  File "/Users/lgp/Desktop/python-workspace/demo/app/views/public.py", line 201, in kline_huobi
    datas = byteify(udata)['data']  # 将unicode的key和value转为string
KeyError: 'data'
2018-04-24 20:06:01,694 39777-123145547587584 ERROR: Failed when updating the huobi prices [in /Users/lgp/Desktop/python-workspace/demo/app/jobs.py:52]
Traceback (most recent call last):
  File "/Users/lgp/Desktop/python-workspace/demo/app/jobs.py", line 50, in huobi_update_prices
    kline_huobi(app)
  File "/Users/lgp/Desktop/python-workspace/demo/app/views/public.py", line 201, in kline_huobi
    datas = byteify(udata)['data']  # 将unicode的key和value转为string
KeyError: 'data'
2018-04-24 20:21:51,030 39777-123145547587584 ERROR: Failed when updating the huobi prices [in /Users/lgp/Desktop/python-workspace/demo/app/jobs.py:52]
Traceback (most recent call last):
  File "/Users/lgp/Desktop/python-workspace/demo/app/jobs.py", line 50, in huobi_update_prices
    kline_huobi(app)
  File "/Users/lgp/Desktop/python-workspace/demo/app/views/public.py", line 201, in kline_huobi
    datas = byteify(udata)['data']  # 将unicode的key和value转为string
KeyError: 'data'
2018-04-24 22:10:03,917 39777-123145547587584 ERROR: Failed when updating the huobi prices [in /Users/lgp/Desktop/python-workspace/demo/app/jobs.py:52]
Traceback (most recent call last):
  File "/Users/lgp/Desktop/python-workspace/demo/app/jobs.py", line 50, in huobi_update_prices
    kline_huobi(app)
  File "/Users/lgp/Desktop/python-workspace/demo/app/views/public.py", line 201, in kline_huobi
    datas = byteify(udata)['data']  # 将unicode的key和value转为string
KeyError: 'data'
2018-04-24 23:02:36,475 39777-123145547587584 ERROR: Failed when updating the huobi prices [in /Users/lgp/Desktop/python-workspace/demo/app/jobs.py:52]
Traceback (most recent call last):
  File "/Users/lgp/Desktop/python-workspace/demo/app/jobs.py", line 50, in huobi_update_prices
    kline_huobi(app)
  File "/Users/lgp/Desktop/python-workspace/demo/app/views/public.py", line 201, in kline_huobi
    datas = byteify(udata)['data']  # 将unicode的key和value转为string
KeyError: 'data'
2018-04-24 23:11:09,345 39777-123145547587584 ERROR: Failed when updating the huobi prices [in /Users/lgp/Desktop/python-workspace/demo/app/jobs.py:52]
Traceback (most recent call last):
  File "/Users/lgp/Desktop/python-workspace/demo/app/jobs.py", line 50, in huobi_update_prices
    kline_huobi(app)
  File "/Users/lgp/Desktop/python-workspace/demo/app/views/public.py", line 201, in kline_huobi
    datas = byteify(udata)['data']  # 将unicode的key和value转为string
KeyError: 'data'
2018-04-24 23:27:10,356 39777-123145547587584 ERROR: Failed when updating the huobi prices [in /Users/lgp/Desktop/python-workspace/demo/app/jobs.py:52]
Traceback (most recent call last):
  File "/Users/lgp/Desktop/python-workspace/demo/app/jobs.py", line 50, in huobi_update_prices
    kline_huobi(app)
  File "/Users/lgp/Desktop/python-workspace/demo/app/views/public.py", line 201, in kline_huobi
    datas = byteify(udata)['data']  # 将unicode的key和value转为string
KeyError: 'data'
2018-04-24 23:31:14,452 39777-123145547587584 ERROR: Failed when updating the huobi prices [in /Users/lgp/Desktop/python-workspace/demo/app/jobs.py:52]
Traceback (most recent call last):
  File "/Users/lgp/Desktop/python-workspace/demo/app/jobs.py", line 50, in huobi_update_prices
    kline_huobi(app)
  File "/Users/lgp/Desktop/python-workspace/demo/app/views/public.py", line 201, in kline_huobi
    datas = byteify(udata)['data']  # 将unicode的key和value转为string
KeyError: 'data'
2018-04-24 23:51:13,351 39777-123145547587584 ERROR: Failed when updating the huobi prices [in /Users/lgp/Desktop/python-workspace/demo/app/jobs.py:52]
Traceback (most recent call last):
  File "/Users/lgp/Desktop/python-workspace/demo/app/jobs.py", line 50, in huobi_update_prices
    kline_huobi(app)
  File "/Users/lgp/Desktop/python-workspace/demo/app/views/public.py", line 201, in kline_huobi
    datas = byteify(udata)['data']  # 将unicode的key和value转为string
KeyError: 'data'
2018-04-25 00:11:15,384 39777-123145547587584 ERROR: Failed when updating the huobi prices [in /Users/lgp/Desktop/python-workspace/demo/app/jobs.py:52]
Traceback (most recent call last):
  File "/Users/lgp/Desktop/python-workspace/demo/app/jobs.py", line 50, in huobi_update_prices
    kline_huobi(app)
  File "/Users/lgp/Desktop/python-workspace/demo/app/views/public.py", line 201, in kline_huobi
    datas = byteify(udata)['data']  # 将unicode的key和value转为string
KeyError: 'data'
2018-04-25 00:21:13,338 39777-123145547587584 ERROR: Failed when updating the huobi prices [in /Users/lgp/Desktop/python-workspace/demo/app/jobs.py:52]
Traceback (most recent call last):
  File "/Users/lgp/Desktop/python-workspace/demo/app/jobs.py", line 50, in huobi_update_prices
    kline_huobi(app)
  File "/Users/lgp/Desktop/python-workspace/demo/app/views/public.py", line 201, in kline_huobi
    datas = byteify(udata)['data']  # 将unicode的key和value转为string
KeyError: 'data'
2018-04-25 00:31:14,462 39777-123145547587584 ERROR: Failed when updating the huobi prices [in /Users/lgp/Desktop/python-workspace/demo/app/jobs.py:52]
Traceback (most recent call last):
  File "/Users/lgp/Desktop/python-workspace/demo/app/jobs.py", line 50, in huobi_update_prices
    kline_huobi(app)
  File "/Users/lgp/Desktop/python-workspace/demo/app/views/public.py", line 201, in kline_huobi
    datas = byteify(udata)['data']  # 将unicode的key和value转为string
KeyError: 'data'
2018-04-25 00:46:13,357 39777-123145547587584 ERROR: Failed when updating the huobi prices [in /Users/lgp/Desktop/python-workspace/demo/app/jobs.py:52]
Traceback (most recent call last):
  File "/Users/lgp/Desktop/python-workspace/demo/app/jobs.py", line 50, in huobi_update_prices
    kline_huobi(app)
  File "/Users/lgp/Desktop/python-workspace/demo/app/views/public.py", line 201, in kline_huobi
    datas = byteify(udata)['data']  # 将unicode的key和value转为string
KeyError: 'data'
2018-04-25 00:52:13,311 39777-123145547587584 ERROR: Failed when updating the huobi prices [in /Users/lgp/Desktop/python-workspace/demo/app/jobs.py:52]
Traceback (most recent call last):
  File "/Users/lgp/Desktop/python-workspace/demo/app/jobs.py", line 50, in huobi_update_prices
    kline_huobi(app)
  File "/Users/lgp/Desktop/python-workspace/demo/app/views/public.py", line 201, in kline_huobi
    datas = byteify(udata)['data']  # 将unicode的key和value转为string
KeyError: 'data'
2018-04-25 01:01:13,322 39777-123145547587584 ERROR: Failed when updating the huobi prices [in /Users/lgp/Desktop/python-workspace/demo/app/jobs.py:52]
Traceback (most recent call last):
  File "/Users/lgp/Desktop/python-workspace/demo/app/jobs.py", line 50, in huobi_update_prices
    kline_huobi(app)
  File "/Users/lgp/Desktop/python-workspace/demo/app/views/public.py", line 201, in kline_huobi
    datas = byteify(udata)['data']  # 将unicode的key和value转为string
KeyError: 'data'
2018-04-25 01:13:12,329 39777-123145547587584 ERROR: Failed when updating the huobi prices [in /Users/lgp/Desktop/python-workspace/demo/app/jobs.py:52]
Traceback (most recent call last):
  File "/Users/lgp/Desktop/python-workspace/demo/app/jobs.py", line 50, in huobi_update_prices
    kline_huobi(app)
  File "/Users/lgp/Desktop/python-workspace/demo/app/views/public.py", line 201, in kline_huobi
    datas = byteify(udata)['data']  # 将unicode的key和value转为string
KeyError: 'data'
2018-04-25 01:25:13,326 39777-123145547587584 ERROR: Failed when updating the huobi prices [in /Users/lgp/Desktop/python-workspace/demo/app/jobs.py:52]
Traceback (most recent call last):
  File "/Users/lgp/Desktop/python-workspace/demo/app/jobs.py", line 50, in huobi_update_prices
    kline_huobi(app)
  File "/Users/lgp/Desktop/python-workspace/demo/app/views/public.py", line 201, in kline_huobi
    datas = byteify(udata)['data']  # 将unicode的key和value转为string
KeyError: 'data'
2018-04-25 01:41:12,330 39777-123145547587584 ERROR: Failed when updating the huobi prices [in /Users/lgp/Desktop/python-workspace/demo/app/jobs.py:52]
Traceback (most recent call last):
  File "/Users/lgp/Desktop/python-workspace/demo/app/jobs.py", line 50, in huobi_update_prices
    kline_huobi(app)
  File "/Users/lgp/Desktop/python-workspace/demo/app/views/public.py", line 201, in kline_huobi
    datas = byteify(udata)['data']  # 将unicode的key和value转为string
KeyError: 'data'
2018-04-25 01:55:12,321 39777-123145547587584 ERROR: Failed when updating the huobi prices [in /Users/lgp/Desktop/python-workspace/demo/app/jobs.py:52]
Traceback (most recent call last):
  File "/Users/lgp/Desktop/python-workspace/demo/app/jobs.py", line 50, in huobi_update_prices
    kline_huobi(app)
  File "/Users/lgp/Desktop/python-workspace/demo/app/views/public.py", line 201, in kline_huobi
    datas = byteify(udata)['data']  # 将unicode的key和value转为string
KeyError: 'data'
2018-04-25 02:04:12,337 39777-123145547587584 ERROR: Failed when updating the huobi prices [in /Users/lgp/Desktop/python-workspace/demo/app/jobs.py:52]
Traceback (most recent call last):
  File "/Users/lgp/Desktop/python-workspace/demo/app/jobs.py", line 50, in huobi_update_prices
    kline_huobi(app)
  File "/Users/lgp/Desktop/python-workspace/demo/app/views/public.py", line 201, in kline_huobi
    datas = byteify(udata)['data']  # 将unicode的key和value转为string
KeyError: 'data'
2018-04-25 02:26:12,319 39777-123145547587584 ERROR: Failed when updating the huobi prices [in /Users/lgp/Desktop/python-workspace/demo/app/jobs.py:52]
Traceback (most recent call last):
  File "/Users/lgp/Desktop/python-workspace/demo/app/jobs.py", line 50, in huobi_update_prices
    kline_huobi(app)
  File "/Users/lgp/Desktop/python-workspace/demo/app/views/public.py", line 201, in kline_huobi
    datas = byteify(udata)['data']  # 将unicode的key和value转为string
KeyError: 'data'
2018-04-25 02:31:11,405 39777-123145547587584 ERROR: Failed when updating the huobi prices [in /Users/lgp/Desktop/python-workspace/demo/app/jobs.py:52]
Traceback (most recent call last):
  File "/Users/lgp/Desktop/python-workspace/demo/app/jobs.py", line 50, in huobi_update_prices
    kline_huobi(app)
  File "/Users/lgp/Desktop/python-workspace/demo/app/views/public.py", line 201, in kline_huobi
    datas = byteify(udata)['data']  # 将unicode的key和value转为string
KeyError: 'data'
2018-04-25 02:47:08,350 39777-123145547587584 ERROR: Failed when updating the huobi prices [in /Users/lgp/Desktop/python-workspace/demo/app/jobs.py:52]
Traceback (most recent call last):
  File "/Users/lgp/Desktop/python-workspace/demo/app/jobs.py", line 50, in huobi_update_prices
    kline_huobi(app)
  File "/Users/lgp/Desktop/python-workspace/demo/app/views/public.py", line 201, in kline_huobi
    datas = byteify(udata)['data']  # 将unicode的key和value转为string
KeyError: 'data'
2018-04-25 03:01:11,311 39777-123145547587584 ERROR: Failed when updating the huobi prices [in /Users/lgp/Desktop/python-workspace/demo/app/jobs.py:52]
Traceback (most recent call last):
  File "/Users/lgp/Desktop/python-workspace/demo/app/jobs.py", line 50, in huobi_update_prices
    kline_huobi(app)
  File "/Users/lgp/Desktop/python-workspace/demo/app/views/public.py", line 201, in kline_huobi
    datas = byteify(udata)['data']  # 将unicode的key和value转为string
KeyError: 'data'
2018-04-25 03:11:12,364 39777-123145547587584 ERROR: Failed when updating the huobi prices [in /Users/lgp/Desktop/python-workspace/demo/app/jobs.py:52]
Traceback (most recent call last):
  File "/Users/lgp/Desktop/python-workspace/demo/app/jobs.py", line 50, in huobi_update_prices
    kline_huobi(app)
  File "/Users/lgp/Desktop/python-workspace/demo/app/views/public.py", line 201, in kline_huobi
    datas = byteify(udata)['data']  # 将unicode的key和value转为string
KeyError: 'data'
2018-04-25 03:27:08,476 39777-123145547587584 ERROR: Failed when updating the huobi prices [in /Users/lgp/Desktop/python-workspace/demo/app/jobs.py:52]
Traceback (most recent call last):
  File "/Users/lgp/Desktop/python-workspace/demo/app/jobs.py", line 50, in huobi_update_prices
    kline_huobi(app)
  File "/Users/lgp/Desktop/python-workspace/demo/app/views/public.py", line 201, in kline_huobi
    datas = byteify(udata)['data']  # 将unicode的key和value转为string
KeyError: 'data'
2018-04-25 03:41:11,340 39777-123145547587584 ERROR: Failed when updating the huobi prices [in /Users/lgp/Desktop/python-workspace/demo/app/jobs.py:52]
Traceback (most recent call last):
  File "/Users/lgp/Desktop/python-workspace/demo/app/jobs.py", line 50, in huobi_update_prices
    kline_huobi(app)
  File "/Users/lgp/Desktop/python-workspace/demo/app/views/public.py", line 201, in kline_huobi
    datas = byteify(udata)['data']  # 将unicode的key和value转为string
KeyError: 'data'
2018-04-25 03:51:11,353 39777-123145547587584 ERROR: Failed when updating the huobi prices [in /Users/lgp/Desktop/python-workspace/demo/app/jobs.py:52]
Traceback (most recent call last):
  File "/Users/lgp/Desktop/python-workspace/demo/app/jobs.py", line 50, in huobi_update_prices
    kline_huobi(app)
  File "/Users/lgp/Desktop/python-workspace/demo/app/views/public.py", line 201, in kline_huobi
    datas = byteify(udata)['data']  # 将unicode的key和value转为string
KeyError: 'data'
2018-04-25 04:05:11,520 39777-123145547587584 ERROR: Failed when updating the huobi prices [in /Users/lgp/Desktop/python-workspace/demo/app/jobs.py:52]
Traceback (most recent call last):
  File "/Users/lgp/Desktop/python-workspace/demo/app/jobs.py", line 50, in huobi_update_prices
    kline_huobi(app)
  File "/Users/lgp/Desktop/python-workspace/demo/app/views/public.py", line 201, in kline_huobi
    datas = byteify(udata)['data']  # 将unicode的key和value转为string
KeyError: 'data'
2018-04-25 04:31:37,353 39777-123145547587584 ERROR: Failed when updating the huobi prices [in /Users/lgp/Desktop/python-workspace/demo/app/jobs.py:52]
Traceback (most recent call last):
  File "/Users/lgp/Desktop/python-workspace/demo/app/jobs.py", line 50, in huobi_update_prices
    kline_huobi(app)
  File "/Users/lgp/Desktop/python-workspace/demo/app/views/public.py", line 201, in kline_huobi
    datas = byteify(udata)['data']  # 将unicode的key和value转为string
KeyError: 'data'
2018-04-25 04:45:59,482 39777-123145547587584 ERROR: Failed when updating the huobi prices [in /Users/lgp/Desktop/python-workspace/demo/app/jobs.py:52]
Traceback (most recent call last):
  File "/Users/lgp/Desktop/python-workspace/demo/app/jobs.py", line 50, in huobi_update_prices
    kline_huobi(app)
  File "/Users/lgp/Desktop/python-workspace/demo/app/views/public.py", line 201, in kline_huobi
    datas = byteify(udata)['data']  # 将unicode的key和value转为string
KeyError: 'data'
2018-04-25 09:13:09,704 39777-123145547587584 ERROR: Failed when updating the huobi prices [in /Users/lgp/Desktop/python-workspace/demo/app/jobs.py:52]
Traceback (most recent call last):
  File "/Users/lgp/Desktop/python-workspace/demo/app/jobs.py", line 50, in huobi_update_prices
    kline_huobi(app)
  File "/Users/lgp/Desktop/python-workspace/demo/app/views/public.py", line 201, in kline_huobi
    datas = byteify(udata)['data']  # 将unicode的key和value转为string
KeyError: 'data'
2018-04-25 09:27:06,819 39777-123145547587584 ERROR: Failed when updating the huobi prices [in /Users/lgp/Desktop/python-workspace/demo/app/jobs.py:52]
Traceback (most recent call last):
  File "/Users/lgp/Desktop/python-workspace/demo/app/jobs.py", line 50, in huobi_update_prices
    kline_huobi(app)
  File "/Users/lgp/Desktop/python-workspace/demo/app/views/public.py", line 201, in kline_huobi
    datas = byteify(udata)['data']  # 将unicode的key和value转为string
KeyError: 'data'
2018-04-25 10:09:49,167 39777-123145547587584 ERROR: Failed when updating the huobi prices [in /Users/lgp/Desktop/python-workspace/demo/app/jobs.py:52]
Traceback (most recent call last):
  File "/Users/lgp/Desktop/python-workspace/demo/app/jobs.py", line 50, in huobi_update_prices
    kline_huobi(app)
  File "/Users/lgp/Desktop/python-workspace/demo/app/views/public.py", line 201, in kline_huobi
    datas = byteify(udata)['data']  # 将unicode的key和value转为string
KeyError: 'data'
2018-04-25 10:14:30,878 39777-123145547587584 ERROR: Failed when updating the huobi prices [in /Users/lgp/Desktop/python-workspace/demo/app/jobs.py:52]
Traceback (most recent call last):
  File "/Users/lgp/Desktop/python-workspace/demo/app/jobs.py", line 50, in huobi_update_prices
    kline_huobi(app)
  File "/Users/lgp/Desktop/python-workspace/demo/app/views/public.py", line 201, in kline_huobi
    datas = byteify(udata)['data']  # 将unicode的key和value转为string
KeyError: 'data'
2018-04-25 10:25:24,189 39777-123145547587584 ERROR: Failed when updating the huobi prices [in /Users/lgp/Desktop/python-workspace/demo/app/jobs.py:52]
Traceback (most recent call last):
  File "/Users/lgp/Desktop/python-workspace/demo/app/jobs.py", line 50, in huobi_update_prices
    kline_huobi(app)
  File "/Users/lgp/Desktop/python-workspace/demo/app/views/public.py", line 201, in kline_huobi
    datas = byteify(udata)['data']  # 将unicode的key和value转为string
KeyError: 'data'
2018-04-25 10:37:17,916 39777-123145547587584 ERROR: Failed when updating the huobi prices [in /Users/lgp/Desktop/python-workspace/demo/app/jobs.py:52]
Traceback (most recent call last):
  File "/Users/lgp/Desktop/python-workspace/demo/app/jobs.py", line 50, in huobi_update_prices
    kline_huobi(app)
  File "/Users/lgp/Desktop/python-workspace/demo/app/views/public.py", line 201, in kline_huobi
    datas = byteify(udata)['data']  # 将unicode的key和value转为string
KeyError: 'data'
2018-04-25 10:37:53,144 39777-123145547587584 ERROR: Failed when updating the huobi prices [in /Users/lgp/Desktop/python-workspace/demo/app/jobs.py:52]
Traceback (most recent call last):
  File "/Users/lgp/Desktop/python-workspace/demo/app/jobs.py", line 50, in huobi_update_prices
    kline_huobi(app)
  File "/Users/lgp/Desktop/python-workspace/demo/app/views/public.py", line 201, in kline_huobi
    datas = byteify(udata)['data']  # 将unicode的key和value转为string
KeyError: 'data'
2018-04-25 11:04:04,162 40571-123145364537344 ERROR: Failed when updating the huobi prices [in /Users/lgp/Desktop/python-workspace/demo/app/jobs.py:52]
Traceback (most recent call last):
  File "/Users/lgp/Desktop/python-workspace/demo/app/jobs.py", line 50, in huobi_update_prices
    kline_huobi(app)
  File "/Users/lgp/Desktop/python-workspace/demo/app/views/public.py", line 215, in kline_huobi
    price.save()
  File "/Users/lgp/Desktop/python-workspace/demo/app/mongosupport/mongosupport.py", line 855, in save
    if not self.validate():
  File "/Users/lgp/Desktop/python-workspace/demo/app/mongosupport/mongosupport.py", line 483, in validate
    self._validate_required(self)
  File "/Users/lgp/Desktop/python-workspace/demo/app/mongosupport/mongosupport.py", line 548, in _validate_required
    self._raise_exception(DataError, rf, "%s is required" % rf)
  File "/Users/lgp/Desktop/python-workspace/demo/app/mongosupport/mongosupport.py", line 572, in _raise_exception
    raise exception(message)
DataError: ex is required
2018-04-25 11:04:35,120 40571-123145364537344 ERROR: Failed when updating the huobi prices [in /Users/lgp/Desktop/python-workspace/demo/app/jobs.py:52]
Traceback (most recent call last):
  File "/Users/lgp/Desktop/python-workspace/demo/app/jobs.py", line 50, in huobi_update_prices
    kline_huobi(app)
  File "/Users/lgp/Desktop/python-workspace/demo/app/views/public.py", line 215, in kline_huobi
    price.save()
  File "/Users/lgp/Desktop/python-workspace/demo/app/mongosupport/mongosupport.py", line 855, in save
    if not self.validate():
  File "/Users/lgp/Desktop/python-workspace/demo/app/mongosupport/mongosupport.py", line 483, in validate
    self._validate_required(self)
  File "/Users/lgp/Desktop/python-workspace/demo/app/mongosupport/mongosupport.py", line 548, in _validate_required
    self._raise_exception(DataError, rf, "%s is required" % rf)
  File "/Users/lgp/Desktop/python-workspace/demo/app/mongosupport/mongosupport.py", line 572, in _raise_exception
    raise exception(message)
DataError: ex is required
2018-04-25 11:05:05,804 40571-123145364537344 ERROR: Failed when updating the huobi prices [in /Users/lgp/Desktop/python-workspace/demo/app/jobs.py:52]
Traceback (most recent call last):
  File "/Users/lgp/Desktop/python-workspace/demo/app/jobs.py", line 50, in huobi_update_prices
    kline_huobi(app)
  File "/Users/lgp/Desktop/python-workspace/demo/app/views/public.py", line 215, in kline_huobi
    price.save()
  File "/Users/lgp/Desktop/python-workspace/demo/app/mongosupport/mongosupport.py", line 855, in save
    if not self.validate():
  File "/Users/lgp/Desktop/python-workspace/demo/app/mongosupport/mongosupport.py", line 483, in validate
    self._validate_required(self)
  File "/Users/lgp/Desktop/python-workspace/demo/app/mongosupport/mongosupport.py", line 548, in _validate_required
    self._raise_exception(DataError, rf, "%s is required" % rf)
  File "/Users/lgp/Desktop/python-workspace/demo/app/mongosupport/mongosupport.py", line 572, in _raise_exception
    raise exception(message)
DataError: ex is required
2018-04-25 11:05:36,943 40571-123145364537344 ERROR: Failed when updating the huobi prices [in /Users/lgp/Desktop/python-workspace/demo/app/jobs.py:52]
Traceback (most recent call last):
  File "/Users/lgp/Desktop/python-workspace/demo/app/jobs.py", line 50, in huobi_update_prices
    kline_huobi(app)
  File "/Users/lgp/Desktop/python-workspace/demo/app/views/public.py", line 215, in kline_huobi
    price.save()
  File "/Users/lgp/Desktop/python-workspace/demo/app/mongosupport/mongosupport.py", line 855, in save
    if not self.validate():
  File "/Users/lgp/Desktop/python-workspace/demo/app/mongosupport/mongosupport.py", line 483, in validate
    self._validate_required(self)
  File "/Users/lgp/Desktop/python-workspace/demo/app/mongosupport/mongosupport.py", line 548, in _validate_required
    self._raise_exception(DataError, rf, "%s is required" % rf)
  File "/Users/lgp/Desktop/python-workspace/demo/app/mongosupport/mongosupport.py", line 572, in _raise_exception
    raise exception(message)
DataError: ex is required
2018-04-25 11:06:12,472 40591-123145390481408 ERROR: Failed when updating the huobi prices [in /Users/lgp/Desktop/python-workspace/demo/app/jobs.py:52]
Traceback (most recent call last):
  File "/Users/lgp/Desktop/python-workspace/demo/app/jobs.py", line 50, in huobi_update_prices
    kline_huobi(app)
  File "/Users/lgp/Desktop/python-workspace/demo/app/views/public.py", line 216, in kline_huobi
    price.save()
  File "/Users/lgp/Desktop/python-workspace/demo/app/mongosupport/mongosupport.py", line 855, in save
    if not self.validate():
  File "/Users/lgp/Desktop/python-workspace/demo/app/mongosupport/mongosupport.py", line 483, in validate
    self._validate_required(self)
  File "/Users/lgp/Desktop/python-workspace/demo/app/mongosupport/mongosupport.py", line 548, in _validate_required
    self._raise_exception(DataError, rf, "%s is required" % rf)
  File "/Users/lgp/Desktop/python-workspace/demo/app/mongosupport/mongosupport.py", line 572, in _raise_exception
    raise exception(message)
DataError: ex is required
2018-04-25 11:07:54,706 40603-123145490780160 ERROR: Failed when updating the huobi prices [in /Users/lgp/Desktop/python-workspace/demo/app/jobs.py:52]
Traceback (most recent call last):
  File "/Users/lgp/Desktop/python-workspace/demo/app/jobs.py", line 50, in huobi_update_prices
    kline_huobi(app)
  File "/Users/lgp/Desktop/python-workspace/demo/app/views/public.py", line 202, in kline_huobi
    datas = byteify(udata)['data']  # 将unicode的key和value转为string
KeyError: 'data'
2018-04-25 11:09:00,556 40603-123145490780160 ERROR: Failed when updating the huobi prices [in /Users/lgp/Desktop/python-workspace/demo/app/jobs.py:52]
Traceback (most recent call last):
  File "/Users/lgp/Desktop/python-workspace/demo/app/jobs.py", line 50, in huobi_update_prices
    kline_huobi(app)
  File "/Users/lgp/Desktop/python-workspace/demo/app/views/public.py", line 202, in kline_huobi
    datas = byteify(udata)['data']  # 将unicode的key和value转为string
KeyError: 'data'
2018-04-25 11:26:12,788 40748-123145449631744 ERROR: Failed when updating the huobi prices [in /Users/lgp/Desktop/python-workspace/demo/app/jobs.py:52]
Traceback (most recent call last):
  File "/Users/lgp/Desktop/python-workspace/demo/app/jobs.py", line 50, in huobi_update_prices
    kline_huobi(app)
  File "/Users/lgp/Desktop/python-workspace/demo/app/views/public.py", line 204, in kline_huobi
    datas = byteify(udata)['data']  # 将unicode的key和value转为string
KeyError: 'data'
2018-04-25 11:42:13,893 40748-123145449631744 ERROR: Failed when updating the huobi prices [in /Users/lgp/Desktop/python-workspace/demo/app/jobs.py:52]
Traceback (most recent call last):
  File "/Users/lgp/Desktop/python-workspace/demo/app/jobs.py", line 50, in huobi_update_prices
    kline_huobi(app)
  File "/Users/lgp/Desktop/python-workspace/demo/app/views/public.py", line 204, in kline_huobi
    datas = byteify(udata)['data']  # 将unicode的key和value转为string
KeyError: 'data'
2018-04-25 11:42:49,094 40748-123145449631744 ERROR: Failed when updating the huobi prices [in /Users/lgp/Desktop/python-workspace/demo/app/jobs.py:52]
Traceback (most recent call last):
  File "/Users/lgp/Desktop/python-workspace/demo/app/jobs.py", line 50, in huobi_update_prices
    kline_huobi(app)
  File "/Users/lgp/Desktop/python-workspace/demo/app/views/public.py", line 204, in kline_huobi
    datas = byteify(udata)['data']  # 将unicode的key和value转为string
KeyError: 'data'
2018-04-25 11:43:24,212 40748-123145449631744 ERROR: Failed when updating the huobi prices [in /Users/lgp/Desktop/python-workspace/demo/app/jobs.py:52]
Traceback (most recent call last):
  File "/Users/lgp/Desktop/python-workspace/demo/app/jobs.py", line 50, in huobi_update_prices
    kline_huobi(app)
  File "/Users/lgp/Desktop/python-workspace/demo/app/views/public.py", line 204, in kline_huobi
    datas = byteify(udata)['data']  # 将unicode的key和value转为string
KeyError: 'data'
2018-04-25 11:59:58,580 40748-123145449631744 ERROR: Failed when updating the huobi prices [in /Users/lgp/Desktop/python-workspace/demo/app/jobs.py:52]
Traceback (most recent call last):
  File "/Users/lgp/Desktop/python-workspace/demo/app/jobs.py", line 50, in huobi_update_prices
    kline_huobi(app)
  File "/Users/lgp/Desktop/python-workspace/demo/app/views/public.py", line 204, in kline_huobi
    datas = byteify(udata)['data']  # 将unicode的key和value转为string
KeyError: 'data'
2018-04-25 12:01:05,019 40748-123145449631744 ERROR: Failed when updating the huobi prices [in /Users/lgp/Desktop/python-workspace/demo/app/jobs.py:52]
Traceback (most recent call last):
  File "/Users/lgp/Desktop/python-workspace/demo/app/jobs.py", line 50, in huobi_update_prices
    kline_huobi(app)
  File "/Users/lgp/Desktop/python-workspace/demo/app/views/public.py", line 204, in kline_huobi
    datas = byteify(udata)['data']  # 将unicode的key和value转为string
KeyError: 'data'
2018-04-25 12:08:21,606 40748-123145449631744 ERROR: Failed when updating the huobi prices [in /Users/lgp/Desktop/python-workspace/demo/app/jobs.py:52]
Traceback (most recent call last):
  File "/Users/lgp/Desktop/python-workspace/demo/app/jobs.py", line 50, in huobi_update_prices
    kline_huobi(app)
  File "/Users/lgp/Desktop/python-workspace/demo/app/views/public.py", line 204, in kline_huobi
    datas = byteify(udata)['data']  # 将unicode的key和value转为string
KeyError: 'data'
2018-04-25 12:09:28,225 40748-123145449631744 ERROR: Failed when updating the huobi prices [in /Users/lgp/Desktop/python-workspace/demo/app/jobs.py:52]
Traceback (most recent call last):
  File "/Users/lgp/Desktop/python-workspace/demo/app/jobs.py", line 50, in huobi_update_prices
    kline_huobi(app)
  File "/Users/lgp/Desktop/python-workspace/demo/app/views/public.py", line 204, in kline_huobi
    datas = byteify(udata)['data']  # 将unicode的key和value转为string
KeyError: 'data'
2018-04-25 12:18:56,698 40748-123145449631744 ERROR: Failed when updating the huobi prices [in /Users/lgp/Desktop/python-workspace/demo/app/jobs.py:52]
Traceback (most recent call last):
  File "/Users/lgp/Desktop/python-workspace/demo/app/jobs.py", line 50, in huobi_update_prices
    kline_huobi(app)
  File "/Users/lgp/Desktop/python-workspace/demo/app/views/public.py", line 204, in kline_huobi
    datas = byteify(udata)['data']  # 将unicode的key和value转为string
KeyError: 'data'
2018-04-25 12:26:16,896 40748-123145449631744 ERROR: Failed when updating the huobi prices [in /Users/lgp/Desktop/python-workspace/demo/app/jobs.py:52]
Traceback (most recent call last):
  File "/Users/lgp/Desktop/python-workspace/demo/app/jobs.py", line 50, in huobi_update_prices
    kline_huobi(app)
  File "/Users/lgp/Desktop/python-workspace/demo/app/views/public.py", line 204, in kline_huobi
    datas = byteify(udata)['data']  # 将unicode的key和value转为string
KeyError: 'data'
2018-04-25 12:41:31,268 40869-123145435955200 ERROR: Failed when updating the huobi prices [in /Users/lgp/Desktop/python-workspace/demo/app/jobs.py:52]
Traceback (most recent call last):
  File "/Users/lgp/Desktop/python-workspace/demo/app/jobs.py", line 50, in huobi_update_prices
    kline_huobi(app)
  File "/Users/lgp/Desktop/python-workspace/demo/app/views/public.py", line 204, in kline_huobi
    datas = byteify(udata)['data']  # 将unicode的key和value转为string
KeyError: 'data'
2018-04-25 13:06:36,259 40869-123145435955200 ERROR: Failed when updating the huobi prices [in /Users/lgp/Desktop/python-workspace/demo/app/jobs.py:52]
Traceback (most recent call last):
  File "/Users/lgp/Desktop/python-workspace/demo/app/jobs.py", line 50, in huobi_update_prices
    kline_huobi(app)
  File "/Users/lgp/Desktop/python-workspace/demo/app/views/public.py", line 204, in kline_huobi
    datas = byteify(udata)['data']  # 将unicode的key和value转为string
KeyError: 'data'
2018-04-25 14:02:22,527 40869-123145435955200 ERROR: Failed when updating the huobi prices [in /Users/lgp/Desktop/python-workspace/demo/app/jobs.py:52]
Traceback (most recent call last):
  File "/Users/lgp/Desktop/python-workspace/demo/app/jobs.py", line 50, in huobi_update_prices
    kline_huobi(app)
  File "/Users/lgp/Desktop/python-workspace/demo/app/views/public.py", line 204, in kline_huobi
    datas = byteify(udata)['data']  # 将unicode的key和value转为string
KeyError: 'data'
2018-04-25 14:18:02,232 40941-123145497681920 ERROR: Failed when updating the huobi prices [in /Users/lgp/Desktop/python-workspace/demo/app/jobs.py:52]
Traceback (most recent call last):
  File "/Users/lgp/Desktop/python-workspace/demo/app/jobs.py", line 50, in huobi_update_prices
    kline_huobi(app)
  File "/Users/lgp/Desktop/python-workspace/demo/app/views/public.py", line 205, in kline_huobi
    datas = byteify(udata)['data']  # 将unicode的key和value转为string
KeyError: 'data'
2018-04-25 14:20:03,391 40959-123145398874112 ERROR: Failed when updating the huobi prices [in /Users/lgp/Desktop/python-workspace/demo/app/jobs.py:52]
Traceback (most recent call last):
  File "/Users/lgp/Desktop/python-workspace/demo/app/jobs.py", line 50, in huobi_update_prices
    kline_huobi(app)
  File "/Users/lgp/Desktop/python-workspace/demo/app/views/public.py", line 205, in kline_huobi
    datas = byteify(udata)['data']  # 将unicode的key和value转为string
KeyError: 'data'
2018-05-02 10:28:12,159 49782-123145546584064 ERROR: Failed when updating the huobi prices [in /Users/lgp/Desktop/python-workspace/demo/app/jobs.py:52]
Traceback (most recent call last):
  File "/Users/lgp/Desktop/python-workspace/demo/app/jobs.py", line 50, in huobi_update_prices
    kline_huobi_new(app)
  File "/Users/lgp/Desktop/python-workspace/demo/app/views/public.py", line 250, in kline_huobi_new
    kline_huobi()
  File "/Users/lgp/Desktop/python-workspace/demo/app/views/public.py", line 276, in kline_huobi
    return jsonify(success=True, message=_('Save the post successfully.'))
  File "/Users/lgp/Desktop/python-workspace/venv/lib/python2.7/site-packages/flask/json.py", line 251, in jsonify
    if current_app.config['JSONIFY_PRETTYPRINT_REGULAR'] and not request.is_xhr:
  File "/Users/lgp/Desktop/python-workspace/venv/lib/python2.7/site-packages/werkzeug/local.py", line 347, in __getattr__
    return getattr(self._get_current_object(), name)
  File "/Users/lgp/Desktop/python-workspace/venv/lib/python2.7/site-packages/werkzeug/local.py", line 306, in _get_current_object
    return self.__local()
  File "/Users/lgp/Desktop/python-workspace/venv/lib/python2.7/site-packages/flask/globals.py", line 51, in _find_app
    raise RuntimeError(_app_ctx_err_msg)
RuntimeError: Working outside of application context.

This typically means that you attempted to use functionality that needed
to interface with the current application object in a way.  To solve
this set up an application context with app.app_context().  See the
documentation for more information.
2018-05-02 10:28:42,819 49782-123145546584064 ERROR: Failed when updating the huobi prices [in /Users/lgp/Desktop/python-workspace/demo/app/jobs.py:52]
Traceback (most recent call last):
  File "/Users/lgp/Desktop/python-workspace/demo/app/jobs.py", line 50, in huobi_update_prices
    kline_huobi_new(app)
  File "/Users/lgp/Desktop/python-workspace/demo/app/views/public.py", line 250, in kline_huobi_new
    kline_huobi()
  File "/Users/lgp/Desktop/python-workspace/demo/app/views/public.py", line 276, in kline_huobi
    return jsonify(success=True, message=_('Save the post successfully.'))
  File "/Users/lgp/Desktop/python-workspace/venv/lib/python2.7/site-packages/flask/json.py", line 251, in jsonify
    if current_app.config['JSONIFY_PRETTYPRINT_REGULAR'] and not request.is_xhr:
  File "/Users/lgp/Desktop/python-workspace/venv/lib/python2.7/site-packages/werkzeug/local.py", line 347, in __getattr__
    return getattr(self._get_current_object(), name)
  File "/Users/lgp/Desktop/python-workspace/venv/lib/python2.7/site-packages/werkzeug/local.py", line 306, in _get_current_object
    return self.__local()
  File "/Users/lgp/Desktop/python-workspace/venv/lib/python2.7/site-packages/flask/globals.py", line 51, in _find_app
    raise RuntimeError(_app_ctx_err_msg)
RuntimeError: Working outside of application context.

This typically means that you attempted to use functionality that needed
to interface with the current application object in a way.  To solve
this set up an application context with app.app_context().  See the
documentation for more information.
2018-05-02 10:29:13,242 49782-123145546584064 ERROR: Failed when updating the huobi prices [in /Users/lgp/Desktop/python-workspace/demo/app/jobs.py:52]
Traceback (most recent call last):
  File "/Users/lgp/Desktop/python-workspace/demo/app/jobs.py", line 50, in huobi_update_prices
    kline_huobi_new(app)
  File "/Users/lgp/Desktop/python-workspace/demo/app/views/public.py", line 250, in kline_huobi_new
    kline_huobi()
  File "/Users/lgp/Desktop/python-workspace/demo/app/views/public.py", line 276, in kline_huobi
    return jsonify(success=True, message=_('Save the post successfully.'))
  File "/Users/lgp/Desktop/python-workspace/venv/lib/python2.7/site-packages/flask/json.py", line 251, in jsonify
    if current_app.config['JSONIFY_PRETTYPRINT_REGULAR'] and not request.is_xhr:
  File "/Users/lgp/Desktop/python-workspace/venv/lib/python2.7/site-packages/werkzeug/local.py", line 347, in __getattr__
    return getattr(self._get_current_object(), name)
  File "/Users/lgp/Desktop/python-workspace/venv/lib/python2.7/site-packages/werkzeug/local.py", line 306, in _get_current_object
    return self.__local()
  File "/Users/lgp/Desktop/python-workspace/venv/lib/python2.7/site-packages/flask/globals.py", line 51, in _find_app
    raise RuntimeError(_app_ctx_err_msg)
RuntimeError: Working outside of application context.

This typically means that you attempted to use functionality that needed
to interface with the current application object in a way.  To solve
this set up an application context with app.app_context().  See the
documentation for more information.
2018-05-02 10:29:43,925 49782-123145546584064 ERROR: Failed when updating the huobi prices [in /Users/lgp/Desktop/python-workspace/demo/app/jobs.py:52]
Traceback (most recent call last):
  File "/Users/lgp/Desktop/python-workspace/demo/app/jobs.py", line 50, in huobi_update_prices
    kline_huobi_new(app)
  File "/Users/lgp/Desktop/python-workspace/demo/app/views/public.py", line 250, in kline_huobi_new
    kline_huobi()
  File "/Users/lgp/Desktop/python-workspace/demo/app/views/public.py", line 276, in kline_huobi
    return jsonify(success=True, message=_('Save the post successfully.'))
  File "/Users/lgp/Desktop/python-workspace/venv/lib/python2.7/site-packages/flask/json.py", line 251, in jsonify
    if current_app.config['JSONIFY_PRETTYPRINT_REGULAR'] and not request.is_xhr:
  File "/Users/lgp/Desktop/python-workspace/venv/lib/python2.7/site-packages/werkzeug/local.py", line 347, in __getattr__
    return getattr(self._get_current_object(), name)
  File "/Users/lgp/Desktop/python-workspace/venv/lib/python2.7/site-packages/werkzeug/local.py", line 306, in _get_current_object
    return self.__local()
  File "/Users/lgp/Desktop/python-workspace/venv/lib/python2.7/site-packages/flask/globals.py", line 51, in _find_app
    raise RuntimeError(_app_ctx_err_msg)
RuntimeError: Working outside of application context.

This typically means that you attempted to use functionality that needed
to interface with the current application object in a way.  To solve
this set up an application context with app.app_context().  See the
documentation for more information.
2018-05-02 10:30:14,601 49782-123145546584064 ERROR: Failed when updating the huobi prices [in /Users/lgp/Desktop/python-workspace/demo/app/jobs.py:52]
Traceback (most recent call last):
  File "/Users/lgp/Desktop/python-workspace/demo/app/jobs.py", line 50, in huobi_update_prices
    kline_huobi_new(app)
  File "/Users/lgp/Desktop/python-workspace/demo/app/views/public.py", line 250, in kline_huobi_new
    kline_huobi()
  File "/Users/lgp/Desktop/python-workspace/demo/app/views/public.py", line 276, in kline_huobi
    return jsonify(success=True, message=_('Save the post successfully.'))
  File "/Users/lgp/Desktop/python-workspace/venv/lib/python2.7/site-packages/flask/json.py", line 251, in jsonify
    if current_app.config['JSONIFY_PRETTYPRINT_REGULAR'] and not request.is_xhr:
  File "/Users/lgp/Desktop/python-workspace/venv/lib/python2.7/site-packages/werkzeug/local.py", line 347, in __getattr__
    return getattr(self._get_current_object(), name)
  File "/Users/lgp/Desktop/python-workspace/venv/lib/python2.7/site-packages/werkzeug/local.py", line 306, in _get_current_object
    return self.__local()
  File "/Users/lgp/Desktop/python-workspace/venv/lib/python2.7/site-packages/flask/globals.py", line 51, in _find_app
    raise RuntimeError(_app_ctx_err_msg)
RuntimeError: Working outside of application context.

This typically means that you attempted to use functionality that needed
to interface with the current application object in a way.  To solve
this set up an application context with app.app_context().  See the
documentation for more information.
